Workbook
Name PROJECT_YEARS: 'Assumptions'!$C$9
Name FX_VND_PER_USD: 'Assumptions'!$C$41
Name PV_CAPEX: 'Assumptions'!$C$44
Name BESS_CAPEX: 'Assumptions'!$C$45
Name OTHER_CAPEX: 'Assumptions'!$C$46
Name TOTAL_CAPEX: 'Assumptions'!$C$47
Name OM_YEAR1: 'Assumptions'!$C$49
Name ESC_OM: 'Assumptions'!$C$50
Name ESC_ENERGY: 'Assumptions'!$C$59
Name ESC_CAPACITY: 'Assumptions'!$C$60
Name PV_DEGRADATION: 'Assumptions'!$C$61
Name ESCO_DISCOUNT: 'Assumptions'!$C$65
Name DEMAND_SHARE: 'Assumptions'!$C$66
Name DEBT_FRACTION: 'Assumptions'!$C$69
Name DEBT_RATE: 'Assumptions'!$C$70
Name DEBT_TERM_YEARS: 'Assumptions'!$C$71
Name DEBT_PRINCIPAL: 'Assumptions'!$C$72
Name EQUITY_INVESTMENT: 'Assumptions'!$C$73
Name DEBT_PAYMENT: 'Assumptions'!$C$74
Name DISC_RATE: 'Assumptions'!$C$75
Name CIT_RATE: 'Assumptions'!$C$78
Name CIT_HOLIDAY_YEARS: 'Assumptions'!$C$79
Name CIT_REDUCED_YEARS: 'Assumptions'!$C$80
Name CIT_REDUCED_FRACTION: 'Assumptions'!$C$81
Name CIT_LOSS_CF_YEARS: 'Assumptions'!$C$82
Name CIT_CLOCK_CAP_YEAR: 'Assumptions'!$C$83
Name PV_DEP_YEARS: 'Assumptions'!$C$84
Name BESS_DEP_YEARS: 'Assumptions'!$C$85
Name BAU_BILL_Y1: 'Assumptions'!$C$87
Name OPT_BILL_Y1: 'Assumptions'!$C$88
Name BAU_DEMAND_Y1: 'Assumptions'!$C$89
Name OPT_DEMAND_Y1: 'Assumptions'!$C$90
Name BASE_DEMAND_SAVINGS: 'Assumptions'!$C$91
Name BASE_SERVED_RETAIL: 'Assumptions'!$C$92
Name BASE_ENERGY_REV: 'Assumptions'!$C$93
Name BASE_GRID_ARB: 'Assumptions'!$C$94

Sheet Cover
B2: Investment Case Workbook - Factory A Vietnam ESCO E2E
B3: ESCO discount-to-EVN tariff (behind-the-meter) · prepared 2026-09-12 · REopt dispatch + proforma_vietnam financial engine
B4: REopt run UUID: 69801894-8577-41c6-9786-72529c4277c0
B6: Model validation status | C6: =IF(COUNTIF('Pro Forma (Audit)'!F87:F95,"REVIEW")+COUNTIF('FX Sensitivity'!F5:F8,"REVIEW")=0,"ALL CHECKS PASS","REVIEW REQUIRED") | D6: Live tie-out of every Excel-derived metric against the engine
B8: Colour legend
B9: Hardcoded input / engine output | C9: Case file terms, REopt dispatch results, 8760-h settlement totals, tie-out references
B10: Live Excel formula (white) | C10: Everything derivable is a formula - trace with Excel's formula auditing tools
B11: PASS / REVIEW check cell | C11: Excel-vs-engine tie-out at stated tolerances
B13: Contents
B14: Executive Summary | C14: Headline KPIs for both counterparties
B15: Assumptions | C15: Every case input & contract term with unit, source and named cell
B16: Model Basis | C16: Methodology, settlement math, simplifications register
B17: Pro Forma (Audit) | C17: Full cash flow rebuilt with live formulas + engine tie-out
B18: FX Sensitivity | C18: USD returns under VND depreciation (editable)
B19: Buyer Analysis | C19: Offtaker savings vs business-as-usual
B20: Developer Returns | C20: Sources & uses, coverage, equity cash flow
B21: Technical Results | C21: System sizing, year-1 energy balance, bill comparison
B22: Dispatch Profile | C22: 8760-h dispatch incl. original PV generation; chart shows the peak-load week
B23: Load Duration | C23: Load and net-load duration curves
B25: Prepared for investment and lending review. Figures are model outputs, not offers; REopt sizing is optimizer output and may shift with solver versions.
B26: Regenerate offline anytime: python -m proforma_vietnam.rebuild_report --case-dir <case>.

Sheet Executive Summary
B1: Investment & PPA Negotiation Summary - Factory A Vietnam ESCO E2E
B2: ESCO discount-to-EVN tariff (behind-the-meter) · prepared 2026-09-12 · REopt dispatch + proforma_vietnam financial model
B4: Project & System
B5: PV Size (kW) | C5: 4568.0646
B6: Battery Power (kW) | C6: 1452.17
B7: Battery Energy (kWh) | C7: 5679.34
B8: Total Investment (USD) | C8: 2990365.4
B10: Contract Terms
B11: ESCO Energy Price (fraction of EVN tariff) | C11: 0.9
B12: Demand Savings Share to ESCO | C12: 0.8
B13: Analysis Period (Years) | C13: 20
B15: Developer (Seller) Returns
B16: Equity IRR | C16: 0.16475869
B17: Project IRR | C17: 0.12841066
B18: NPV (USD) | C18: 773959.87 | D18: At owner discount rate
B19: Minimum DSCR (debt years) | C19: -0.92015088 | D19: Lender covenant view
B20: Average DSCR | C20: 1.1481816
B21: Simple Payback (Years) | C21: 7.8276663
B22: Equity Investment (USD) | C22: 897109.62
B23: Debt Principal (USD) | C23: 2093255.8
B25: Buyer (Offtaker) Outcome
B26: Year 1 BAU Cost (USD) | C26: 727943.72
B27: Year 1 Cost With Project (USD) | C27: 680553
B28: Year 1 Buyer Savings (USD) | C28: 47390.719
B29: Year 1 Savings (% of BAU) | C29: 0.065102174
B30: First 10 Years Buyer Savings (USD) | C30: 555445.55 | D30: Cumulative, years 1-10
B31: First 10 Years Savings (% of BAU) | C31: 0.063553793
B32: Lifetime Buyer Savings (USD) | C32: 1337443.6 | D32: Sum over analysis period
B33: Lifetime Savings (% of BAU) | C33: 0.061699411
B35: Model Basis & Conventions
B36: • ESCO is paid a discount to the time-specific EVN tariff for project-served energy.
B37: • PV degradation, O&M escalation and battery replacement (REopt schedule) are applied across the analysis period.
B38: • PV straight-line depreciation over 20 years (Circular 45/2013/TT-BTC permits 7-20 years for generating equipment).
B39: • Vietnam CIT: 4-year exemption + 9-year 50% reduction from first profitable year; 5-year tax-loss carryforward.
B40: • All USD figures at the fixed contract exchange rate (see Assumptions); FX drift between VND revenue and USD reporting is quantified on the FX Sensitivity sheet.

Sheet Assumptions
B1: Assumptions & Model Inputs
B2: Shaded cells are hardcoded inputs (case file or engine output); named cells drive every formula on the Pro Forma (Audit) sheet.
B4: Project & Run
B5: Case name | C5: Factory A Vietnam ESCO E2E | E5: case.json
B6: Financing structure | C6: ESCO discount-to-EVN (behind-the-meter) | E6: proforma_vietnam.structures
B7: REopt run UUID | C7: 69801894-8577-41c6-9786-72529c4277c0 | E7: REopt API
B8: Report prepared | C8: 2026-09-12
B9: Analysis period | C9: 20 | D9: years | E9: proforma_vietnam.defaults replacement policy (PROJECT_YEARS) unless case.json financial.analysis_years overrides
B10: Tariff year | C10: 2025 | E10: case.json tariff.year
B11: Voltage level | C11: 22-110kV | E11: case.json tariff.voltage_level
B12: TOU schedule | C12: current | E12: case.json tariff.tou_schedule
B13: Site & Load Profile (case.json)
B14: Latitude | C14: 10.8231 | D14: deg | E14: case.json site.latitude
B15: Longitude | C15: 106.6297 | D15: deg | E15: case.json site.longitude
B16: Load profile file | C16: Sample Load Profile/Emivest_clean.csv | E16: case.json load_profile.path (8760 hourly kW)
B17: Load year | C17: 2025 | E17: case.json load_profile.year
B18: PV Technology (case.json)
B19: PV minimum size | C19: 0 | D19: kW | E19: case.json technologies.pv.min_kw
B20: PV maximum size | C20: 10000 | D20: kW | E20: case.json technologies.pv.max_kw
B21: PV installed cost | C21: 480 | D21: USD/kW | E21: case.json technologies.pv.installed_cost_per_kw
B22: PV O&M cost | C22: 6 | D22: USD/kW/yr | E22: case.json technologies.pv.om_cost_per_kw
B23: PV degradation (case input) | C23: 0.005 | D23: per year | E23: case.json technologies.pv.degradation_fraction
B24: PVWatts tilt | C24: 10 | E24: case.json technologies.pv.pvwatts (production factor inputs)
B25: PVWatts azimuth | C25: 180 | E25: case.json technologies.pv.pvwatts (production factor inputs)
B26: PVWatts array_type | C26: 1 | E26: case.json technologies.pv.pvwatts (production factor inputs)
B27: PVWatts module_type | C27: 0 | E27: case.json technologies.pv.pvwatts (production factor inputs)
B28: PVWatts losses | C28: 14 | E28: case.json technologies.pv.pvwatts (production factor inputs)
B29: PVWatts dc_ac_ratio | C29: 1.2 | E29: case.json technologies.pv.pvwatts (production factor inputs)
B30: Storage Technology (case.json)
B31: Storage minimum power | C31: 0 | D31: kW | E31: case.json technologies.storage.min_kw
B32: Storage maximum power | C32: 5000 | D32: kW | E32: case.json technologies.storage.max_kw
B33: Storage minimum energy | C33: 0 | D33: kWh | E33: case.json technologies.storage.min_kwh
B34: Storage maximum energy | C34: 20000 | D34: kWh | E34: case.json technologies.storage.max_kwh
B35: Storage cost per kW | C35: 80 | D35: USD/kW | E35: case.json technologies.storage.installed_cost_per_kw
B36: Storage cost per kWh | C36: 120 | D36: USD/kWh | E36: case.json technologies.storage.installed_cost_per_kwh
B37: Storage fixed cost | C37: 0 | D37: USD | E37: case.json technologies.storage.installed_cost_constant
B38: O&M (fraction of installed cost) | C38: 0.01 | D38: per year | E38: case.json technologies.storage.om_cost_fraction_of_installed_cost
B39: Currency & FX
B40: Model currency | C40: USD | E40: EVN tariff converted VND→USD before REopt; see Model Basis
B41: Contract exchange rate | C41: 26300 | D41: VND per USD | E41: case.json tariff.exchange_rate_vnd_per_usd
...

Sheet Model Basis
B1: Model Basis, Conventions & Simplifications
B3: 1. Model architecture
B4: • REopt (NLR optimization engine) selects PV/BESS sizing and hourly dispatch against the EVN time-of-use tariff over an 8760-hour year.
B5: • proforma_vietnam post-processes the REopt run: an hourly ND57/2025 DPPA settlement layer (when applicable) and a 20-year developer cash flow with Vietnam tax and debt.
B6: • This workbook is generated from that engine. The Pro Forma (Audit) sheet re-derives the full cash flow with live Excel formulas from the named inputs on the Assumptions sheet; the Checks block ties every metric back to the engine (PASS/REVIEW).
B8: 2. Currency & FX
B9: • All money flows are computed in USD at the fixed contract rate (26,300 VND/USD).
B10: • Underlying revenue is VND-denominated (EVN tariff, FMP market, DPPA fees). Holding FX flat for the analysis period is a simplification: the FX Sensitivity sheet quantifies USD-reported returns under 0-3%/yr VND depreciation.
B11: • Sheets that show VND amounts (Hourly/Monthly Settlement, DPPA fee inputs) are VND-native regulatory quantities, not conversions.
B12: • Debt is assumed VND-denominated (local bank), so DSCR is FX-neutral.
B14: 3. Settlement math - ESCO discount-to-EVN
B15: • The ESCO is paid a contracted fraction of the time-specific EVN tariff for project-served energy (PV→load, plus battery→load when the battery cannot grid-charge).
... B47: • EVN retail tariff (current & QĐ963 TOU structures) as configured in the case file.

Sheet Pro Forma (Audit)
A1: Pro Forma (Audit) - every white cell is a live Excel formula
A2: Shaded cells are hardcoded engine outputs (REopt dispatch / 8760-h settlement / tie-out reference). All other cells derive from the named cells on the Assumptions sheet. Currency: USD at the fixed contract FX rate.
A4: TIMELINE & INDEXATION
A5: Year | B5: index | C5: 0 | D5: 1 | E5: 2 | F5: 3 | G5: 4 | H5: 5 | I5: 6 | J5: 7 | K5: 8 | L5: 9 | M5: 10 | N5: 11 | O5: 12 | P5: 13 | Q5: 14 | R5: 15 | S5: 16 | T5: 17 | U5: 18 | V5: 19 | W5: 20
A6: EVN energy escalation factor | B6: index | D6: =(1+ESC_ENERGY)^(D$5-1) | E6: =(1+ESC_ENERGY)^(E$5-1) | F6: =(1+ESC_ENERGY)^(F$5-1) | G6: =(1+ESC_ENERGY)^(G$5-1) | H6: =(1+ESC_ENERGY)^(H$5-1) | I6: =(1+ESC_ENERGY)^(I$5-1) | J6: =(1+ESC_ENERGY)^(J$5-1) | K6: =(1+ESC_ENERGY)^(K$5-1) | ... W6: =(1+ESC_ENERGY)^(W$5-1)
A7: EVN capacity escalation factor | B7: index | D7: =(1+ESC_CAPACITY)^(D$5-1) | E7: =(1+ESC_CAPACITY)^(E$5-1) | F7: =(1+ESC_CAPACITY)^(F$5-1) | G7: =(1+ESC_CAPACITY)^(G$5-1) | H7: =(1+ESC_CAPACITY)^(H$5-1) | I7: =(1+ESC_CAPACITY)^(I$5-1) | J7: =(1+ESC_CAPACITY)^(J$5-1) | K7: =(1+ESC_CAPACITY)^(K$5-1) | ... W7: =(1+ESC_CAPACITY)^(W$5-1)
A8: O&M escalation factor | B8: index | D8: =(1+ESC_OM)^(D$5-1) | E8: =(1+ESC_OM)^(E$5-1) | F8: =(1+ESC_OM)^(F$5-1) | G8: =(1+ESC_OM)^(G$5-1) | H8: =(1+ESC_OM)^(H$5-1) | I8: =(1+ESC_OM)^(I$5-1) | J8: =(1+ESC_OM)^(J$5-1) | K8: =(1+ESC_OM)^(K$5-1) | ... W8: =(1+ESC_OM)^(W$5-1)
A9: PV degradation factor | B9: index | D9: =(1-PV_DEGRADATION)^(D$5-1) | E9: =(1-PV_DEGRADATION)^(E$5-1) | F9: =(1-PV_DEGRADATION)^(F$5-1) | G9: =(1-PV_DEGRADATION)^(G$5-1) | H9: =(1-PV_DEGRADATION)^(H$5-1) | I9: =(1-PV_DEGRADATION)^(I$5-1) | J9: =(1-PV_DEGRADATION)^(J$5-1) | K9: =(1-PV_DEGRADATION)^(K$5-1) | ... W9: =(1-PV_DEGRADATION)^(W$5-1)
A11: REVENUE (USD)
A12: ESCO energy revenue (discount-to-EVN) | B12: USD | D12: =BASE_ENERGY_REV*D6*D9 | E12: =BASE_ENERGY_REV*E6*E9 | F12: =BASE_ENERGY_REV*F6*F9 | G12: =BASE_ENERGY_REV*G6*G9 | H12: =BASE_ENERGY_REV*H6*H9 | I12: =BASE_ENERGY_REV*I6*I9 | J12: =BASE_ENERGY_REV*J6*J9 | K12: =BASE_ENERGY_REV*K6*K9 | ... W12: =BASE_ENERGY_REV*W6*W9
A13: Demand charge savings (total) | B13: USD | D13: =BASE_DEMAND_SAVINGS*D7 | E13: =BASE_DEMAND_SAVINGS*E7 | F13: =BASE_DEMAND_SAVINGS*F7 | G13: =BASE_DEMAND_SAVINGS*G7 | H13: =BASE_DEMAND_SAVINGS*H7 | I13: =BASE_DEMAND_SAVINGS*I7 | J13: =BASE_DEMAND_SAVINGS*J7 | K13: =BASE_DEMAND_SAVINGS*K7 | ... W13: =BASE_DEMAND_SAVINGS*W7
A14: ESCO share of demand savings | B14: USD | D14: =D13*DEMAND_SHARE | E14: =E13*DEMAND_SHARE | F14: =F13*DEMAND_SHARE | G14: =G13*DEMAND_SHARE | H14: =H13*DEMAND_SHARE | I14: =I13*DEMAND_SHARE | J14: =J13*DEMAND_SHARE | K14: =K13*DEMAND_SHARE | ... W14: =W13*DEMAND_SHARE
A15: Grid arbitrage revenue | B15: USD | D15: =BASE_GRID_ARB*D6 | E15: =BASE_GRID_ARB*E6 | F15: =BASE_GRID_ARB*F6 | G15: =BASE_GRID_ARB*G6 | H15: =BASE_GRID_ARB*H6 | I15: =BASE_GRID_ARB*I6 | J15: =BASE_GRID_ARB*J6 | K15: =BASE_GRID_ARB*K6 | ... W15: =BASE_GRID_ARB*W6
A16: Total developer revenue | B16: USD | D16: =D12+D14+D15 | E16: =E12+E14+E15 | F16: =F12+F14+F15 | G16: =G12+G14+G15 | H16: =H12+H14+H15 | I16: =I12+I14+I15 | J16: =J12+J14+J15 | K16: =K12+K14+K15 | ... W16: =W12+W14+W15
A18: OPERATING COSTS (USD)
A19: O&M | B19: USD | D19: =OM_YEAR1*D8 | E19: =OM_YEAR1*E8 | F19: =OM_YEAR1*F8 | G19: =OM_YEAR1*G8 | H19: =OM_YEAR1*H8 | I19: =OM_YEAR1*I8 | J19: =OM_YEAR1*J8 | K19: =OM_YEAR1*K8 | ... W19: =OM_YEAR1*W8
A20: Equipment replacement (engine schedule) | B20: USD | D20: 0 | E20: 0 | F20: 0 | G20: 0 | H20: 0 | I20: 0 | J20: 0 | K20: 0 | L20: 0 | M20: 797694.4 | N20: 219267.1 | O20: 0 | P20: 0 | Q20: 0 | R20: 0 | S20: 0 | T20: 0 | U20: 0 | V20: 0 | W20: 0
A21: EBITDA | B21: USD | D21: =D16-D19-D20 | E21: =E16-E19-E20 | F21: =F16-F19-F20 | G21: =G16-G19-G20 | H21: =H16-H19-H20 | I21: =I16-I19-I20 | J21: =J16-J19-J20 | K21: =K16-K19-K20 | ... W21: =W16-W19-W20
A23: DEBT SCHEDULE (USD)
A24: Opening debt balance | B24: USD | D24: =DEBT_PRINCIPAL | E24: =D28 | F24: =E28 | G24: =F28 | H24: =G28 | I24: =H28 | J24: =I28 | K24: =J28 | L24: =K28 | ... W24: =V28
A25: Interest | B25: USD | D25: =IF(D$5<=DEBT_TERM_YEARS,D24*DEBT_RATE,0) | E25: =IF(E$5<=DEBT_TERM_YEARS,E24*DEBT_RATE,0) | F25: =IF(F$5<=DEBT_TERM_YEARS,F24*DEBT_RATE,0) | G25: =IF(G$5<=DEBT_TERM_YEARS,G24*DEBT_RATE,0) | H25: =IF(H$5<=DEBT_TERM_YEARS,H24*DEBT_RATE,0) | I25: =IF(I$5<=DEBT_TERM_YEARS,I24*DEBT_RATE,0) | J25: =IF(J$5<=DEBT_TERM_YEARS,J24*DEBT_RATE,0) | K25: =IF(K$5<=DEBT_TERM_YEARS,K24*DEBT_RATE,0) | ... W25: =IF(W$5<=DEBT_TERM_YEARS,W24*DEBT_RATE,0)
A26: Principal repayment | B26: USD | D26: =IF(D$5<=DEBT_TERM_YEARS,MIN(MAX(DEBT_PAYMENT-D25,0),D24),0) | E26: =IF(E$5<=DEBT_TERM_YEARS,MIN(MAX(DEBT_PAYMENT-E25,0),E24),0) | F26: =IF(F$5<=DEBT_TERM_YEARS,MIN(MAX(DEBT_PAYMENT-F25,0),F24),0) | G26: =IF(G$5<=DEBT_TERM_YEARS,MIN(MAX(DEBT_PAYMENT-G25,0),G24),0) | H26: =IF(H$5<=DEBT_TERM_YEARS,MIN(MAX(DEBT_PAYMENT-H25,0),H24),0) | I26: =IF(I$5<=DEBT_TERM_YEARS,MIN(MAX(DEBT_PAYMENT-I25,0),I24),0) | J26: =IF(J$5<=DEBT_TERM_YEARS,MIN(MAX(DEBT_PAYMENT-J25,0),J24),0) | K26: =IF(K$5<=DEBT_TERM_YEARS,MIN(MAX(DEBT_PAYMENT-K25,0),K24),0) | ... W26: =IF(W$5<=DEBT_TERM_YEARS,MIN(MAX(DEBT_PAYMENT-W25,0),W24),0)
A27: Debt service | B27: USD | D27: =D25+D26 | E27: =E25+E26 | F27: =F25+F26 | G27: =G25+G26 | H27: =H25+H26 | I27: =I25+I26 | J27: =J25+J26 | K27: =K25+K26 | ... W27: =W25+W26
A28: Closing debt balance | B28: USD | D28: =D24-D26 | E28: =E24-E26 | F28: =F24-F26 | G28: =G24-G26 | H28: =H24-H26 | I28: =I24-I26 | J28: =J24-J26 | K28: =K24-K26 | ... W28: =W24-W26
A30: DEPRECIATION & VIETNAM CIT (USD)
A31: PV depreciation (straight-line) | B31: USD | D31: =IF(D$5<=PV_DEP_YEARS,PV_CAPEX/PV_DEP_YEARS,0) | E31: =IF(E$5<=PV_DEP_YEARS,PV_CAPEX/PV_DEP_YEARS,0) | F31: =IF(F$5<=PV_DEP_YEARS,PV_CAPEX/PV_DEP_YEARS,0) | G31: =IF(G$5<=PV_DEP_YEARS,PV_CAPEX/PV_DEP_YEARS,0) | H31: =IF(H$5<=PV_DEP_YEARS,PV_CAPEX/PV_DEP_YEARS,0) | I31: =IF(I$5<=PV_DEP_YEARS,PV_CAPEX/PV_DEP_YEARS,0) | J31: =IF(J$5<=PV_DEP_YEARS,PV_CAPEX/PV_DEP_YEARS,0) | K31: =IF(K$5<=PV_DEP_YEARS,PV_CAPEX/PV_DEP_YEARS,0) | ... W31: =IF(W$5<=PV_DEP_YEARS,PV_CAPEX/PV_DEP_YEARS,0)
A32: BESS depreciation (straight-line) | B32: USD | D32: =IF(D$5<=BESS_DEP_YEARS,BESS_CAPEX/BESS_DEP_YEARS,0) | E32: =IF(E$5<=BESS_DEP_YEARS,BESS_CAPEX/BESS_DEP_YEARS,0) | F32: =IF(F$5<=BESS_DEP_YEARS,BESS_CAPEX/BESS_DEP_YEARS,0) | G32: =IF(G$5<=BESS_DEP_YEARS,BESS_CAPEX/BESS_DEP_YEARS,0) | H32: =IF(H$5<=BESS_DEP_YEARS,BESS_CAPEX/BESS_DEP_YEARS,0) | I32: =IF(I$5<=BESS_DEP_YEARS,BESS_CAPEX/BESS_DEP_YEARS,0) | J32: =IF(J$5<=BESS_DEP_YEARS,BESS_CAPEX/BESS_DEP_YEARS,0) | K32: =IF(K$5<=BESS_DEP_YEARS,BESS_CAPEX/BESS_DEP_YEARS,0) | ... W32: =IF(W$5<=BESS_DEP_YEARS,BESS_CAPEX/BESS_DEP_YEARS,0)
A33: Replacement depreciation (in-service yr 10) | B33: USD | D33: =IF(AND(D$5>=10,D$5<=10+BESS_DEP_YEARS-1),$M$20/BESS_DEP_YEARS,0) | E33: =IF(AND(E$5>=10,E$5<=10+BESS_DEP_YEARS-1),$M$20/BESS_DEP_YEARS,0) | F33: =IF(AND(F$5>=10,F$5<=10+BESS_DEP_YEARS-1),$M$20/BESS_DEP_YEARS,0) | G33: =IF(AND(G$5>=10,G$5<=10+BESS_DEP_YEARS-1),$M$20/BESS_DEP_YEARS,0) | H33: =IF(AND(H$5>=10,H$5<=10+BESS_DEP_YEARS-1),$M$20/BESS_DEP_YEARS,0) | I33: =IF(AND(I$5>=10,I$5<=10+BESS_DEP_YEARS-1),$M$20/BESS_DEP_YEARS,0) | J33: =IF(AND(J$5>=10,J$5<=10+BESS_DEP_YEARS-1),$M$20/BESS_DEP_YEARS,0) | K33: =IF(AND(K$5>=10,K$5<=10+BESS_DEP_YEARS-1),$M$20/BESS_DEP_YEARS,0) | ... W33: =IF(AND(W$5>=10,W$5<=10+BESS_DEP_YEARS-1),$M$20/BESS_DEP_YEARS,0)
A34: Replacement depreciation (in-service yr 11) | B34: USD | D34: =IF(AND(D$5>=11,D$5<=11+BESS_DEP_YEARS-1),$N$20/BESS_DEP_YEARS,0) | E34: =IF(AND(E$5>=11,E$5<=11+BESS_DEP_YEARS-1),$N$20/BESS_DEP_YEARS,0) | F34: =IF(AND(F$5>=11,F$5<=11+BESS_DEP_YEARS-1),$N$20/BESS_DEP_YEARS,0) | G34: =IF(AND(G$5>=11,G$5<=11+BESS_DEP_YEARS-1),$N$20/BESS_DEP_YEARS,0) | H34: =IF(AND(H$5>=11,H$5<=11+BESS_DEP_YEARS-1),$N$20/BESS_DEP_YEARS,0) | I34: =IF(AND(I$5>=11,I$5<=11+BESS_DEP_YEARS-1),$N$20/BESS_DEP_YEARS,0) | J34: =IF(AND(J$5>=11,J$5<=11+BESS_DEP_YEARS-1),$N$20/BESS_DEP_YEARS,0) | K34: =IF(AND(K$5>=11,K$5<=11+BESS_DEP_YEARS-1),$N$20/BESS_DEP_YEARS,0) | ... W34: =IF(AND(W$5>=11,W$5<=11+BESS_DEP_YEARS-1),$N$20/BESS_DEP_YEARS,0)
A35: Total depreciation | B35: USD | D35: =D31+D32+D33+D34 | E35: =E31+E32+E33+E34 | F35: =F31+F32+F33+F34 | G35: =G31+G32+G33+G34 | H35: =H31+H32+H33+H34 | I35: =I31+I32+I33+I34 | J35: =J31+J32+J33+J34 | K35: =K31+K32+K33+K34 | ... W35: =W31+W32+W33+W34
A36: Taxable income before loss relief (EBT) | B36: USD | D36: =D21+D20-D35-D25 | E36: =E21+E20-E35-E25 | F36: =F21+F20-F35-F25 | G36: =G21+G20-G35-G25 | H36: =H21+H20-H35-H25 | I36: =I21+I20-I35-I25 | J36: =J21+J20-J35-J25 | K36: =K21+K20-K35-K25 | ... W36: =W21+W20-W35-W25
A37: New tax loss arising | B37: USD | D37: =MAX(-D36,0) | E37: =MAX(-E36,0) | F37: =MAX(-F36,0) | G37: =MAX(-G36,0) | H37: =MAX(-H36,0) | I37: =MAX(-I36,0) | J37: =MAX(-J36,0) | K37: =MAX(-K36,0) | ... W37: =MAX(-W36,0)
A38: Assessable income (pre-relief) | B38: USD | D38: =MAX(D36,0) | E38: =MAX(E36,0) | F38: =MAX(F36,0) | G38: =MAX(G36,0) | H38: =MAX(H36,0) | I38: =MAX(I36,0) | J38: =MAX(J36,0) | K38: =MAX(K36,0) | ... W38: =MAX(W36,0)
A39: Loss vintage aged 1y - available | B39: USD | D39: 0 | E39: =D37 | F39: =E37 | G39: =F37 | H39: =G37 | I39: =H37 | J39: =I37 | K39: =J37 | L39: =K37 | ... W39: =V37
A40: Loss vintage aged 2y - available | B40: USD | D40: 0 | E40: =MAX(D39-D48,0) | F40: =MAX(E39-E48,0) | G40: =MAX(F39-F48,0) | H40: =MAX(G39-G48,0) | I40: =MAX(H39-H48,0) | J40: =MAX(I39-I48,0) | K40: =MAX(J39-J48,0) | L40: =MAX(K39-K48,0) | ... W40: =MAX(V39-V48,0)
A41: Loss vintage aged 3y - available | B41: USD | D41: 0 | E41: =MAX(D40-D47,0) | F41: =MAX(E40-E47,0) | G41: =MAX(F40-F47,0) | H41: =MAX(G40-G47,0) | I41: =MAX(H40-H47,0) | J41: =MAX(I40-I47,0) | K41: =MAX(J40-J47,0) | L41: =MAX(K40-K47,0) | ... W41: =MAX(V40-V47,0)
A42: Loss vintage aged 4y - available | B42: USD | D42: 0 | E42: =MAX(D41-D46,0) | F42: =MAX(E41-E46,0) | G42: =MAX(F41-F46,0) | H42: =MAX(G41-G46,0) | I42: =MAX(H41-H46,0) | J42: =MAX(I41-I46,0) | K42: =MAX(J41-J46,0) | L42: =MAX(K41-K46,0) | ... W42: =MAX(V41-V46,0)
A43: Loss vintage aged 5y - available | B43: USD | D43: 0 | E43: =MAX(D42-D45,0) | F43: =MAX(E42-E45,0) | G43: =MAX(F42-F45,0) | H43: =MAX(G42-G45,0) | I43: =MAX(H42-H45,0) | J43: =MAX(I42-I45,0) | K43: =MAX(J42-J45,0) | L43: =MAX(K42-K45,0) | ... W43: =MAX(V42-V45,0)
A44: Loss vintage aged 5y - utilised | B44: USD | D44: =MIN(D43,MAX(D38,0)) | E44: =MIN(E43,MAX(E38,0)) | F44: =MIN(F43,MAX(F38,0)) | G44: =MIN(G43,MAX(G38,0)) | H44: =MIN(H43,MAX(H38,0)) | I44: =MIN(I43,MAX(I38,0)) | J44: =MIN(J43,MAX(J38,0)) | K44: =MIN(K43,MAX(K38,0)) | ... W44: =MIN(W43,MAX(W38,0))
A45: Loss vintage aged 4y - utilised | B45: USD | D45: =MIN(D42,MAX(D38-D44,0)) | E45: =MIN(E42,MAX(E38-E44,0)) | F45: =MIN(F42,MAX(F38-F44,0)) | G45: =MIN(G42,MAX(G38-G44,0)) | H45: =MIN(H42,MAX(H38-H44,0)) | I45: =MIN(I42,MAX(I38-I44,0)) | J45: =MIN(J42,MAX(J38-J44,0)) | K45: =MIN(K42,MAX(K38-K44,0)) | ... W45: =MIN(W42,MAX(W38-W44,0))
...

Sheet FX Sensitivity
A1: FX Sensitivity - VND depreciation vs USD returns
A2: Cash flows are VND-denominated (EVN tariff / DPPA settlement) but reported in USD at the fixed contract rate. Each scenario deflates the year-t USD equity cash flow by (1+d)^t. Debt is assumed VND-denominated, so DSCR is unchanged. The rate cells are editable; engine columns validate the default scenarios.
A4: VND depreciation (per year) | B4: Equity IRR (USD) | C4: Equity NPV (USD) | D4: Equity IRR (engine) | E4: Equity NPV (engine) | F4: Status
A5: 0 | B5: =IRR(B12:V12) | C5: =NPV(DISC_RATE,C12:V12)+B12 | D5: 0.16475869 | E5: 773959.87 | F5: =IF(AND(ABS(B5-D5)<=0.0005,ABS(C5-E5)<=1.0),"PASS","REVIEW")
A6: 0.01 | B6: =IRR(B13:V13) | C6: =NPV(DISC_RATE,C13:V13)+B13 | D6: 0.15322643 | E6: 590114.81 | F6: =IF(AND(ABS(B6-D6)<=0.0005,ABS(C6-E6)<=1.0),"PASS","REVIEW")
A7: 0.02 | B7: =IRR(B14:V14) | C7: =NPV(DISC_RATE,C14:V14)+B14 | D7: 0.14192029 | E7: 432518.29 | F7: =IF(AND(ABS(B7-D7)<=0.0005,ABS(C7-E7)<=1.0),"PASS","REVIEW")
A8: 0.03 | B8: =IRR(B15:V15) | C8: =NPV(DISC_RATE,C15:V15)+B15 | D8: 0.13083368 | E8: 296966.95 | F8: =IF(AND(ABS(B8-D8)<=0.0005,ABS(C8-E8)<=1.0),"PASS","REVIEW")
A10: Helper - FX-adjusted equity cash flow per scenario (USD): CF_t / (1 + d)^t
B11: 0 | C11: 1 | D11: 2 | E11: 3 | F11: 4 | G11: 5 | H11: 6 | I11: 7 | J11: 8 | K11: 9 | L11: 10 | M11: 11 | N11: 12 | O11: 13 | P11: 14 | Q11: 15 | R11: 16 | S11: 17 | T11: 18 | U11: 19 | V11: 20
A12: =A5 | B12: ='Pro Forma (Audit)'!C59/(1+$A5)^B$11 | C12: ='Pro Forma (Audit)'!D59/(1+$A5)^C$11 | D12: ='Pro Forma (Audit)'!E59/(1+$A5)^D$11 | E12: ='Pro Forma (Audit)'!F59/(1+$A5)^E$11 | F12: ='Pro Forma (Audit)'!G59/(1+$A5)^F$11 | G12: ='Pro Forma (Audit)'!H59/(1+$A5)^G$11 | H12: ='Pro Forma (Audit)'!I59/(1+$A5)^H$11 | I12: ='Pro Forma (Audit)'!J59/(1+$A5)^I$11 | ... V12: ='Pro Forma (Audit)'!W59/(1+$A5)^V$11
A13: =A6 | B13: ='Pro Forma (Audit)'!C59/(1+$A6)^B$11 | C13: ='Pro Forma (Audit)'!D59/(1+$A6)^C$11 | D13: ='Pro Forma (Audit)'!E59/(1+$A6)^D$11 | E13: ='Pro Forma (Audit)'!F59/(1+$A6)^E$11 | F13: ='Pro Forma (Audit)'!G59/(1+$A6)^F$11 | G13: ='Pro Forma (Audit)'!H59/(1+$A6)^G$11 | H13: ='Pro Forma (Audit)'!I59/(1+$A6)^H$11 | I13: ='Pro Forma (Audit)'!J59/(1+$A6)^I$11 | ... V13: ='Pro Forma (Audit)'!W59/(1+$A6)^V$11
A14: =A7 | B14: ='Pro Forma (Audit)'!C59/(1+$A7)^B$11 | C14: ='Pro Forma (Audit)'!D59/(1+$A7)^C$11 | D14: ='Pro Forma (Audit)'!E59/(1+$A7)^D$11 | E14: ='Pro Forma (Audit)'!F59/(1+$A7)^E$11 | F14: ='Pro Forma (Audit)'!G59/(1+$A7)^F$11 | G14: ='Pro Forma (Audit)'!H59/(1+$A7)^G$11 | H14: ='Pro Forma (Audit)'!I59/(1+$A7)^H$11 | I14: ='Pro Forma (Audit)'!J59/(1+$A7)^I$11 | ... V14: ='Pro Forma (Audit)'!W59/(1+$A7)^V$11
A15: =A8 | B15: ='Pro Forma (Audit)'!C59/(1+$A8)^B$11 | C15: ='Pro Forma (Audit)'!D59/(1+$A8)^C$11 | D15: ='Pro Forma (Audit)'!E59/(1+$A8)^D$11 | E15: ='Pro Forma (Audit)'!F59/(1+$A8)^E$11 | F15: ='Pro Forma (Audit)'!G59/(1+$A8)^F$11 | G15: ='Pro Forma (Audit)'!H59/(1+$A8)^G$11 | H15: ='Pro Forma (Audit)'!I59/(1+$A8)^H$11 | I15: ='Pro Forma (Audit)'!J59/(1+$A8)^I$11 | ... V15: ='Pro Forma (Audit)'!W59/(1+$A8)^V$11

Sheet Buyer Analysis
B1: Buyer Analysis - Cost vs Business-As-Usual
B2: Annual electricity cost with the project compared against the EVN-only baseline (USD)
B4: Year 1 Snapshot
B5: Year 1 BAU Cost (USD) | C5: 727943.72
B6: Year 1 Cost With Project (USD) | C6: 680553
B7: Year 1 Savings (USD) | C7: 47390.719
B8: Year 1 Savings (% of BAU) | C8: 0.065102174
B9: First 10 Years Savings (USD) | C9: 555445.55 | D9: Cumulative, years 1-10
B10: First 10 Years Savings (% of BAU) | C10: 0.063553793
B11: Lifetime Savings (USD) | C11: 1337443.6 | D11: Cumulative over analysis period
B12: Lifetime Savings (% of BAU) | C12: 0.061699411
A14: Year | B14: BAU Cost (USD) | C14: Cost With Project (USD) | D14: Savings (USD) | E14: Savings (% of BAU) | F14: Cumulative Savings (USD)
A15: 1 | B15: 727943.72 | C15: 680553 | D15: 47390.719 | E15: 0.065102174 | F15: 47390.719
A16: 2 | B16: 757061.47 | C16: 708021.55 | D16: 49039.916 | E16: 0.064776663 | F16: 96430.634
A17: 3 | B17: 787343.93 | C17: 736597.42 | D17: 50746.505 | E17: 0.06445278 | F17: 147177.14
A18: 4 | B18: 818837.68 | C18: 766325.2 | D18: 52512.483 | E18: 0.064130516 | F18: 199689.62
A19: 5 | B19: 851591.19 | C19: 797251.27 | D19: 54339.917 | E19: 0.063809863 | F19: 254029.54
A20: 6 | B20: 885654.84 | C20: 829423.89 | D20: 56230.946 | E20: 0.063490814 | F20: 310260.49
A21: 7 | B21: 921081.03 | C21: 862893.25 | D21: 58187.783 | E21: 0.06317336 | F21: 368448.27
A22: 8 | B22: 957924.27 | C22: 897711.56 | D22: 60212.718 | E22: 0.062857493 | F22: 428660.99
A23: 9 | B23: 996241.25 | C23: 933933.12 | D23: 62308.121 | E23: 0.062543205 | F23: 490969.11
A24: 10 | B24: 1036090.9 | C24: 971614.45 | D24: 64476.443 | E24: 0.062230489 | F24: 555445.55
A25: 11 | B25: 1077534.5 | C25: 1010814.3 | D25: 66720.224 | E25: 0.061919337 | F25: 622165.78
A26: 12 | B26: 1120635.9 | C26: 1051593.8 | D26: 69042.087 | E26: 0.06160974 | F26: 691207.86
... A34: 20 | B34: 1533667.6 | C34: 1442892.8 | D34: 90774.794 | E34: 0.059188049 | F34: 1337443.6

Sheet Developer Returns
B1: Developer Returns - Financing & Cash Flow
B2: Seller/ESCO investment case: sources & uses, return metrics and annual equity cash flow (USD)
B4: Sources & Uses
B5: Total Investment (USD) | C5: 2990365.4
B6: Debt Principal (USD) | C6: 2093255.8
B7: Equity Investment (USD) | C7: 897109.62
B9: Return Metrics
B10: Equity IRR | C10: 0.16475869
B11: Project IRR | C11: 0.12841066
B12: NPV (USD) | C12: 773959.87 | D12: At owner discount rate
B13: Minimum DSCR (debt years) | C13: -0.92015088
B14: Average DSCR | C14: 1.1481816
B15: Simple Payback (Years) | C15: 7.8276663
B16: ROI (cumulative equity CF / equity) | C16: 6.6337583
A18: Year | B18: Revenue (USD) | C18: O&M + Replacement (USD) | D18: CIT (USD) | E18: CFADS (USD) | F18: Debt Service (USD) | G18: DSCR | H18: Equity Cash Flow (USD) | I18: Cumulative Equity CF (USD)
A19: 1 | B19: 426516.49 | C19: 35385.325 | D19: 0 | E19: 391131.17 | F19: 319028.31 | G19: 1.2260077 | H19: 72102.857 | I19: -825006.77
A20: 2 | B20: 441359.27 | C20: 36446.885 | D20: 0 | E20: 404912.38 | F20: 319028.31 | G20: 1.2692052 | H20: 85884.071 | I20: -739122.69
A21: 3 | B21: 456718.57 | C21: 37540.291 | D21: 0 | E21: 419178.28 | F21: 319028.31 | G21: 1.3139219 | H21: 100149.97 | I21: -638972.73
A22: 4 | B22: 472612.37 | C22: 38666.5 | D22: 0 | E22: 433945.87 | F22: 319028.31 | G22: 1.3602112 | H22: 114917.56 | I22: -524055.16
A23: 5 | B23: 489059.29 | C23: 39826.495 | D23: 11640.597 | E23: 437592.19 | F23: 319028.31 | G23: 1.3716406 | H23: 118563.88 | I23: -405491.28
A24: 6 | B24: 506078.55 | C24: 41021.29 | D24: 14885.192 | E24: 450172.07 | F24: 319028.31 | G24: 1.4110725 | H24: 131143.76 | I24: -274347.52
A25: 7 | B25: 523690.08 | C25: 42251.929 | D25: 18326.712 | E25: 463111.44 | F25: 319028.31 | G25: 1.4516312 | H25: 144083.13 | I25: -130264.39
A26: 8 | B26: 541914.5 | C26: 43519.487 | D26: 21979.12 | E26: 476415.89 | F26: 319028.31 | G26: 1.4933342 | H26: 157387.58 | I26: 27123.188
A27: 9 | B27: 560773.12 | C27: 44825.071 | D27: 35828.647 | E27: 480119.4 | F27: 319028.31 | G27: 1.5049429 | H27: 161091.09 | I27: 188214.28
A28: 10 | B28: 580288.03 | C28: 843864.22 | D28: 29977.985 | E28: -293554.18 | F28: 319028.31 | G28: -0.92015088 | H28: -612582.49 | I28: -424368.21
A29: 11 | B29: 600482.05 | C29: 266822.02 | D29: 31617.339 | E29: 302042.69 | F29: 0 | H29: 302042.69 | I29: -122325.52
A30: 12 | B30: 621378.82 | C30: 48981.566 | D30: 33564.352 | E30: 538832.91 | F30: 0 | H30: 538832.91 | I30: 416507.39
A31: 13 | B31: 643002.81 | C31: 50451.012 | D31: 35579.806 | E31: 556971.99 | F31: 0 | H31: 556971.99 | I31: 973479.38
A32: 14 | B32: 665379.31 | C32: 51964.543 | D32: 75332.205 | E32: 538082.56 | F32: 0 | H32: 538082.56 | I32: 1511561.9
A33: 15 | B33: 688534.51 | C33: 53523.479 | D33: 79651.458 | E33: 555359.57 | F33: 0 | H33: 555359.57 | I33: 2066921.5
A34: 16 | B34: 712495.51 | C34: 55129.184 | D34: 84122.517 | E34: 573243.81 | F34: 0 | H34: 573243.81 | I34: 2640165.3
A35: 17 | B35: 737290.35 | C35: 56783.059 | D35: 88750.711 | E35: 591756.58 | F35: 0 | H35: 591756.58 | I35: 3231921.9
A36: 18 | B36: 762948.05 | C36: 58486.551 | D36: 113483.91 | E36: 590977.59 | F36: 0 | H36: 590977.59 | I36: 3822899.5
A37: 19 | B37: 789498.65 | C37: 60241.147 | D37: 123924.79 | E37: 605332.71 | F37: 0 | H37: 605332.71 | I37: 4428232.2
A38: 20 | B38: 816973.2 | C38: 62048.382 | D38: 129058.25 | E38: 625866.56 | F38: 0 | H38: 625866.56 | I38: 5054098.8

Sheet Technical Results
A1: Metric | B1: Value
A2: System Sizing
A3: PV Size (kW) | B3: 4568.0646
A4: Battery Power (kW) | B4: 1452.17
A5: Battery Energy (kWh) | B5: 5679.34
A7: Annual Energy Balance (Year 1)
A8: PV to Load (kWh) | B8: 3642896.9
A9: PV to Storage (kWh) | B9: 1600297.7
A10: PV to Grid (kWh) | B10: 0
A11: Storage to Load (kWh) | B11: 1439644.5
A12: Grid to Load (kWh) | B12: 4456680.1
A13: PV Curtailed (kWh) | B13: 1188834.9
A14: Grid to Storage (kWh) | B14: 0
A16: Year-1 Utility Bill Comparison
A17: BAU Utility Bill (USD) | B17: 727943.72
A18: Optimized Utility Bill (USD) | B18: 254036.51
A19: Utility Bill Savings (USD) | B19: 473907.21
A20: BAU Demand Charge (USD) | B20: 0
A21: Optimized Demand Charge (USD) | B21: 0
A22: Demand Charge Savings (USD) | B22: 0
A24: Solar Resource (Year 1)
A25: Annual POA Irradiation (kWh/m²) | B25: 1929.6822
A26: Performance Ratio (Year 1) | B26: 0.72967589

Sheet Dispatch Profile
A1: Hour | B1: Load (kW) | C1: PV Irradiation (W/m²) | D1: PV Generation Total (kW) | E1: PV to Load (kW) | F1: PV to Storage (kW) | G1: PV to Grid (kW) | H1: PV Curtailed (kW) | I1: Grid to Load (kW) | J1: Grid to Storage (kW) | K1: Storage to Load (kW)
A2: 1 | B2: 1020 | C2: 0 | D2: 0 | E2: 0 | F2: 0 | G2: 0 | H2: 0 | I2: 1020 | J2: 0 | K2: 0
A3: 2 | B3: 1078.4 | C3: 0 | D3: 0 | E3: 0 | F3: 0 | G3: 0 | H3: 0 | I3: 1078.4 | J3: 0 | K3: 0
A4: 3 | B4: 906.4 | C4: 0 | D4: 0 | E4: 0 | F4: 0 | G4: 0 | H4: 0 | I4: 906.4 | J4: 0 | K4: 0
A5: 4 | B5: 860.8 | C5: 0 | D5: 0 | E5: 0 | F5: 0 | G5: 0 | H5: 0 | I5: 860.8 | J5: 0 | K5: 0
A6: 5 | B6: 996.8 | C6: 0 | D6: 0 | E6: 0 | F6: 0 | G6: 0 | H6: 0 | I6: 938.453 | J6: 0 | K6: 60.726204
A7: 6 | B7: 983.2 | C7: 0 | D7: 0 | E7: 0 | F7: 0 | G7: 0 | H7: 0 | I7: 0 | J7: 0 | K7: 1023.2917
A8: 7 | B8: 586.4 | C8: 11.75 | D8: 13.39792 | E8: 13.39792 | F8: 0 | G8: 0 | H8: 0 | I8: 0 | J8: 0 | K8: 596.91359
A9: 8 | B9: 104.269 | C9: 120.27 | D9: 414.57054 | E9: 108.52076 | F9: -306.04978 | G9: 0 | H9: 0 | I9: 0 | J9: 0 | K9: 0
A10: 9 | B10: 89.172 | C10: 270.88 | D10: 970.13407 | E10: 92.808148 | F10: -877.32592 | G10: 0 | H10: 0 | I10: 0 | J10: 0 | K10: 0
A11: 10 | B11: 105.232 | C11: 505.48 | D11: 1799.8538 | E11: 109.52302 | F11: -1511.3838 | G11: 0 | H11: 178.947 | I11: 0 | J11: 0 | K11: 0
A12: 11 | B12: 89.626 | C12: 573.07 | D12: 2008.4359 | E12: 93.280661 | F12: -1511.3838 | G12: 0 | H12: 403.77144 | I12: 0 | J12: 0 | K12: 0
A13: 12 | B13: 119.641 | C13: 477.66 | D13: 1658.354 | E13: 124.51958 | F13: -782.37585 | G13: 0 | H13: 751.45854 | I13: 0 | J13: 0 | K13: 0
... A8761: 8760 | B8761: 1216 | C8761: 0 | D8761: 0 | E8761: 0 | F8761: 0 | G8761: 0 | H8761: 0 | I8761: 1216 | J8761: 0 | K8761: 0

Sheet Load Duration
A1: Rank | B1: Load (kW) | C1: Net Load (kW)
A2: 1 | B2: 2428 | C2: 2428
A3: 2 | B3: 2418.5558 | C3: 2418.556
A4: 3 | B4: 2414.4 | C4: 2389.6
A5: 4 | B5: 2405.0087 | C5: 2380.305
A6: 5 | B6: 2390.381 | C6: 2379.2
A7: 6 | B7: 2389.6 | C7: 2369.946
A8: 7 | B8: 2387.844 | C8: 2352
A9: 8 | B9: 2381.0831 | C9: 2350.321
A10: 9 | B10: 2380.3051 | C10: 2342.851
A11: 10 | B11: 2379.2 | C11: 2330.4
A12: 11 | B12: 2378.556 | C12: 2321.335
A13: 12 | B13: 2369.9456 | C13: 2295.2
... A8761: 8760 | B8761: 0 | C8761: 0
