Workbook
Name PROJECT_YEARS: 'Assumptions'!$C$9
Name FX_VND_PER_USD: 'Assumptions'!$C$12
Name PV_CAPEX: 'Assumptions'!$C$15
Name BESS_CAPEX: 'Assumptions'!$C$16
Name OTHER_CAPEX: 'Assumptions'!$C$17
Name TOTAL_CAPEX: 'Assumptions'!$C$18
Name OM_YEAR1: 'Assumptions'!$C$20
Name ESC_OM: 'Assumptions'!$C$21
Name ESC_ENERGY: 'Assumptions'!$C$30
Name ESC_CAPACITY: 'Assumptions'!$C$31
Name PV_DEGRADATION: 'Assumptions'!$C$32
Name ESCO_DISCOUNT: 'Assumptions'!$C$34
Name DEMAND_SHARE: 'Assumptions'!$C$35
Name ESC_STRIKE: 'Assumptions'!$C$38
Name ESC_FEE: 'Assumptions'!$C$39
Name DEBT_FRACTION: 'Assumptions'!$C$48
Name DEBT_RATE: 'Assumptions'!$C$49
Name DEBT_TERM_YEARS: 'Assumptions'!$C$50
Name DEBT_PRINCIPAL: 'Assumptions'!$C$51
Name EQUITY_INVESTMENT: 'Assumptions'!$C$52
Name DEBT_PAYMENT: 'Assumptions'!$C$53
Name DISC_RATE: 'Assumptions'!$C$54
Name CIT_RATE: 'Assumptions'!$C$57
Name CIT_PREF_RATE: 'Assumptions'!$C$58
Name CIT_PREF_YEARS: 'Assumptions'!$C$59
Name CIT_HOLIDAY_YEARS: 'Assumptions'!$C$60
Name CIT_REDUCED_YEARS: 'Assumptions'!$C$61
Name CIT_REDUCED_FRACTION: 'Assumptions'!$C$62
Name CIT_LOSS_CF_YEARS: 'Assumptions'!$C$63
Name CIT_CLOCK_CAP_YEAR: 'Assumptions'!$C$64
Name PV_DEP_YEARS: 'Assumptions'!$C$65
Name BESS_DEP_YEARS: 'Assumptions'!$C$66
Name BAU_BILL_Y1: 'Assumptions'!$C$68
Name OPT_BILL_Y1: 'Assumptions'!$C$69
Name BAU_DEMAND_Y1: 'Assumptions'!$C$70
Name OPT_DEMAND_Y1: 'Assumptions'!$C$71
Name BASE_DEMAND_SAVINGS: 'Assumptions'!$C$72
Name BASE_SERVED_RETAIL: 'Assumptions'!$C$73
Name DPPA_C_DN_Y1: 'Assumptions'!$C$74
Name DPPA_C_DPPA_Y1: 'Assumptions'!$C$75
Name DPPA_C_CL_Y1: 'Assumptions'!$C$76
Name DPPA_C_BL_Y1: 'Assumptions'!$C$77
Name DPPA_CFD_STRIKE_Y1: 'Assumptions'!$C$78
Name DPPA_CFD_OFFSET_Y1: 'Assumptions'!$C$79
Name DPPA_FMP_REV_Y1: 'Assumptions'!$C$80
Name DPPA_MATCHED_RETAIL_Y1: 'Assumptions'!$C$81

Sheet Cover
B2: Investment Case Workbook - Vietnam ESCO / DPPA Case
B3: Grid-connected DPPA with CfD (ND57/2025) · prepared 2026-09-13 · REopt dispatch + proforma_vietnam financial engine
B4: REopt run UUID: 51114e02-ba05-4c15-a826-c4078ec7034a
B6: Model validation status | C6: =IF(COUNTIF('Pro Forma (Audit)'!F97:F105,"REVIEW")+COUNTIF('FX Sensitivity'!F5:F8,"REVIEW")=0,"ALL CHECKS PASS","REVIEW REQUIRED") | D6: Live tie-out of every Excel-derived metric against the engine
B8: Colour legend
B9: Hardcoded input / engine output | C9: Case file terms, REopt dispatch results, 8760-h settlement totals, tie-out references
B10: Live Excel formula (white) | C10: Everything derivable is a formula - trace with Excel's formula auditing tools
B11: PASS / REVIEW check cell | C11: Excel-vs-engine tie-out at stated tolerances
B13: Contents
B14: Executive Summary | C14: Headline KPIs for both counterparties
B15: Assumptions | C15: Every case input & contract term with unit, source and named cell
B16: Model Basis | C16: Methodology, settlement math, simplifications register
B17: Pro Forma (Audit) | C17: Full cash flow rebuilt with live formulas + engine tie-out
B18: FX Sensitivity | C18: USD returns under VND depreciation (editable)
B19: Buyer Analysis | C19: Offtaker savings vs business-as-usual
B20: Developer Returns | C20: Sources & uses, coverage, equity cash flow
B21: Technical Results | C21: System sizing, year-1 energy balance, bill comparison
B22: Dispatch Profile | C22: 8760-h dispatch incl. original PV generation; chart shows the peak-load week
B23: Load Duration | C23: Load and net-load duration curves
B24: Year 1 BAU vs DPPA | C24: Side-by-side year-1 buyer/seller position
B25: Monthly / Hourly Settlement | C25: ND57 fee chain, VND-native (full configuration on Assumptions)
B27: Prepared for investment and lending review. Figures are model outputs, not offers; REopt sizing is optimizer output and may shift with solver versions.
B28: Regenerate offline anytime: python -m proforma_vietnam.rebuild_report --case-dir <case>.

Sheet Executive Summary
B1: Investment & PPA Negotiation Summary - Vietnam ESCO / DPPA Case
B2: Grid-connected DPPA with CfD (ND57/2025) · prepared 2026-09-13 · REopt dispatch + proforma_vietnam financial model
B4: Project & System
B5: PV Size (kW) | C5: 2829.159
B6: Battery Power (kW) | C6: 306.08
B7: Battery Energy (kWh) | C7: 1450.72
B8: Total Investment (USD) | C8: 1556569.1
B10: Contract Terms
B11: CfD Strike Price (VND/kWh) | C11: 2000
B12: CfD Strike Escalation (per year) | C12: 0.04
B13: Annual Contract Volume (kWh) | C13: 7664883.2
B14: Transmission Loss Factor k | C14: 1.026
B15: Distribution Loss Factor K_pp | C15: 1.027263
B16: DPPA Service Fee (VND/kWh) | C16: 360
B17: Settlement Adder C_CL (VND/kWh) | C17: 163.3
B18: Analysis Period (Years) | C18: 20
B20: Developer (Seller) Returns
B21: Equity IRR | C21: 0.28385393
B22: Project IRR | C22: 0.18337348
B23: NPV (USD) | C23: 1137682.3 | D23: At owner discount rate
B24: Minimum DSCR (debt years) | C24: 0.91308881 | D24: Lender covenant view
B25: Average DSCR | C25: 1.7116866
B26: Simple Payback (Years) | C26: 4.1772135
B27: Equity Investment (USD) | C27: 466970.74
B28: Debt Principal (USD) | C28: 1089598.4
B30: Buyer (Offtaker) Outcome
B31: Year 1 BAU Cost (USD) | C31: 731030.93
B32: Year 1 Cost With Project (USD) | C32: 805683.4
B33: Year 1 Buyer Savings (USD) | C33: -74652.466
B34: Year 1 Savings (% of BAU) | C34: -0.10211944
B35: First 10 Years Buyer Savings (USD) | C35: -898833.73 | D35: Cumulative, years 1-10
B36: First 10 Years Savings (% of BAU) | C36: -0.10240977
B37: Lifetime Buyer Savings (USD) | C37: -2236896.5 | D37: Sum over analysis period
B38: Lifetime Savings (% of BAU) | C38: -0.10275748
B40: Model Basis & Conventions
B41: • Buyer settlement quantity Q_Khc = min(hourly load, loss-adjusted generation Q_adj); excess generation is sold by the generator at FMP and never billed to the buyer.
B42: • PV degradation, O&M escalation and battery replacement (REopt schedule) are applied across the analysis period.
B43: • PV straight-line depreciation over 20 years (Circular 45/2013/TT-BTC permits 7-20 years for generating equipment).
B44: • Vietnam CIT: 4-year exemption + 9-year 50% reduction from first profitable year; 5-year tax-loss carryforward.
B45: • All USD figures at the fixed contract exchange rate (see Assumptions); FX drift between VND revenue and USD reporting is quantified on the FX Sensitivity sheet.

Sheet Assumptions
B1: Assumptions & Model Inputs
B2: Shaded cells are hardcoded inputs (case file or engine output); named cells drive every formula on the Pro Forma (Audit) sheet.
B4: Project & Run
B5: Case name | C5: Vietnam case | E5: case.json
B6: Financing structure | C6: Grid DPPA with CfD (ND57/2025) | E6: proforma_vietnam.structures
B7: REopt run UUID | C7: 51114e02-ba05-4c15-a826-c4078ec7034a | E7: REopt API
B8: Report prepared | C8: 2026-09-13
B9: Analysis period | C9: 20 | D9: years | E9: proforma_vietnam.defaults replacement policy (PROJECT_YEARS) unless case.json financial.analysis_years overrides
B10: Currency & FX
B11: Model currency | C11: USD | E11: EVN tariff converted VND→USD before REopt; see Model Basis
B12: Contract exchange rate | C12: 26300 | D12: VND per USD | E12: case.json tariff.exchange_rate_vnd_per_usd
B13: FX treatment | C13: Held flat over the analysis period | E13: Simplification - see FX Sensitivity sheet
B14: Capital Costs
B15: PV capex | C15: 1357996.3 | D15: USD | E15: REopt PV size_kw × installed_cost_per_kw
B16: BESS capex | C16: 198572.8 | D16: USD | E16: REopt ElectricStorage initial_capital_cost
B17: Other capex | C17: 0 | D17: USD | E17: case.json (developer overrides)
B18: Total investment | C18: =PV_CAPEX+BESS_CAPEX+OTHER_CAPEX | D18: USD | E18: Formula: PV + BESS + Other
B19: Operating Costs
B20: Year-1 O&M | C20: 18960.679 | D20: USD/yr | E20: REopt Financial.year_one_om_costs_before_tax
B21: O&M escalation | C21: 0.03 | D21: per year | E21: vietnam_defaults.json / case.json financial.om_escalation_rate
B22: Replacement Policy
B23: BESS replacement year (storage inverter and pack together) | C23: 10 | D23: year | E23: proforma_vietnam.defaults replacement policy unless case.json technologies.storage overrides
B24: BESS replacement cost per kW | D24: USD/kW | E24: proforma_vietnam.defaults replacement policy unless case.json technologies.storage overrides (sent to REopt)
B25: BESS replacement cost per kWh | D25: USD/kWh | E25: proforma_vietnam.defaults replacement policy unless case.json technologies.storage overrides (sent to REopt)
B26: PV inverter replacement year | C26: 11 | D26: year | E26: proforma_vietnam.defaults replacement policy
B27: PV inverter replacement fraction of PV capex | C27: 0.1 | D27: fraction | E27: proforma_vietnam.defaults replacement policy
B28: PV inverter replacement cost | C28: 135799.63 | D28: USD | E28: Engine: fraction x solved PV capex (none booked when the run has no PV)
B29: Tariff & Escalation
B30: EVN energy escalation | C30: 0.04 | D30: per year | E30: case.json tariff.evn_energy_escalation_rate
B31: EVN capacity (demand) escalation | C31: 0.04 | D31: per year | E31: case.json tariff.evn_capacity_escalation_rate
B32: PV degradation | C32: 0.005 | D32: per year | E32: REopt PV.degradation_fraction
B33: Contract Terms
B34: ESCO energy price (fraction of EVN tariff) | C34: 0.9 | D34: fraction | E34: case.json esco_contract.esco_energy_discount_fraction
B35: Demand savings share to ESCO | C35: 0.8 | D35: fraction | E35: case.json esco_contract.demand_savings_esco_share
B36: Grid charging enabled | C36: FALSE | D36: yes/no | E36: case.json esco_contract.grid_charging_enabled
B37: CfD strike price | C37: 2000 | D37: VND/kWh | E37: case.json dppa.cfd_strike_per_kwh_vnd
B38: CfD strike escalation | C38: 0.04 | D38: per year | E38: case.json dppa.cfd_strike_escalation_rate
B39: DPPA fee / FMP escalation | C39: 0.04 | D39: per year | E39: case.json dppa.fee_escalation_rate
B40: Annual CfD contract volume | C40: 7664883.2 | D40: kWh/yr | E40: case.json dppa.cfd_contract_volume_kwh_per_hour
B41: Transmission loss factor k (price-only) | C41: 1.026 | D41: ratio | E41: ND57; CFMP = FMP × k
...

Sheet Model Basis
B1: Model Basis, Conventions & Simplifications
B3: 1. Model architecture
B4: • REopt (NLR optimization engine) selects PV/BESS sizing and hourly dispatch against the EVN time-of-use tariff over an 8760-hour year.
B5: • proforma_vietnam post-processes the REopt run: an hourly ND57/2025 DPPA settlement layer (when applicable) and a 20-year developer cash flow with Vietnam tax and debt.
B6: • This workbook is generated from that engine. The Pro Forma (Audit) sheet re-derives the full cash flow with live Excel formulas from the named inputs on the Assumptions sheet; the Checks block ties every metric back to the engine (PASS/REVIEW).
B8: 2. Currency & FX
B9: • All money flows are computed in USD at the fixed contract rate (26,300 VND/USD).
B10: • Underlying revenue is VND-denominated (EVN tariff, FMP market, DPPA fees). Holding FX flat for the analysis period is a simplification: the FX Sensitivity sheet quantifies USD-reported returns under 0-3%/yr VND depreciation.
B11: • Sheets that show VND amounts (Hourly/Monthly Settlement, DPPA fee inputs) are VND-native regulatory quantities, not conversions.
B12: • Debt is assumed VND-denominated (local bank), so DSCR is FX-neutral.
B14: 3. Settlement math - ND57/2025 grid DPPA with CfD
B15: • Q_adj[h] = Q_re_meter[h] / K_pp × delta - quantity conversion generator→customer uses K_pp only (CD7 Ví dụ 1); k is price-only.
... B50: • EVN retail tariff (current & QĐ963 TOU structures) as configured in the case file.

Sheet Pro Forma (Audit)
A1: Pro Forma (Audit) - every white cell is a live Excel formula
A2: Shaded cells are hardcoded engine outputs (REopt dispatch / 8760-h settlement / tie-out reference). All other cells derive from the named cells on the Assumptions sheet. Currency: USD at the fixed contract FX rate.
A4: TIMELINE & INDEXATION
A5: Year | B5: index | C5: 0 | D5: 1 | E5: 2 | F5: 3 | G5: 4 | H5: 5 | I5: 6 | J5: 7 | K5: 8 | L5: 9 | M5: 10 | N5: 11 | O5: 12 | P5: 13 | Q5: 14 | R5: 15 | S5: 16 | T5: 17 | U5: 18 | V5: 19 | W5: 20
A6: EVN energy escalation factor | B6: index | D6: =(1+ESC_ENERGY)^(D$5-1) | E6: =(1+ESC_ENERGY)^(E$5-1) | F6: =(1+ESC_ENERGY)^(F$5-1) | G6: =(1+ESC_ENERGY)^(G$5-1) | H6: =(1+ESC_ENERGY)^(H$5-1) | I6: =(1+ESC_ENERGY)^(I$5-1) | J6: =(1+ESC_ENERGY)^(J$5-1) | K6: =(1+ESC_ENERGY)^(K$5-1) | ... W6: =(1+ESC_ENERGY)^(W$5-1)
A7: EVN capacity escalation factor | B7: index | D7: =(1+ESC_CAPACITY)^(D$5-1) | E7: =(1+ESC_CAPACITY)^(E$5-1) | F7: =(1+ESC_CAPACITY)^(F$5-1) | G7: =(1+ESC_CAPACITY)^(G$5-1) | H7: =(1+ESC_CAPACITY)^(H$5-1) | I7: =(1+ESC_CAPACITY)^(I$5-1) | J7: =(1+ESC_CAPACITY)^(J$5-1) | K7: =(1+ESC_CAPACITY)^(K$5-1) | ... W7: =(1+ESC_CAPACITY)^(W$5-1)
A8: O&M escalation factor | B8: index | D8: =(1+ESC_OM)^(D$5-1) | E8: =(1+ESC_OM)^(E$5-1) | F8: =(1+ESC_OM)^(F$5-1) | G8: =(1+ESC_OM)^(G$5-1) | H8: =(1+ESC_OM)^(H$5-1) | I8: =(1+ESC_OM)^(I$5-1) | J8: =(1+ESC_OM)^(J$5-1) | K8: =(1+ESC_OM)^(K$5-1) | ... W8: =(1+ESC_OM)^(W$5-1)
A9: PV degradation factor | B9: index | D9: =(1-PV_DEGRADATION)^(D$5-1) | E9: =(1-PV_DEGRADATION)^(E$5-1) | F9: =(1-PV_DEGRADATION)^(F$5-1) | G9: =(1-PV_DEGRADATION)^(G$5-1) | H9: =(1-PV_DEGRADATION)^(H$5-1) | I9: =(1-PV_DEGRADATION)^(I$5-1) | J9: =(1-PV_DEGRADATION)^(J$5-1) | K9: =(1-PV_DEGRADATION)^(K$5-1) | ... W9: =(1-PV_DEGRADATION)^(W$5-1)
A10: DPPA fee / FMP escalation factor | B10: index | D10: =(1+ESC_FEE)^(D$5-1) | E10: =(1+ESC_FEE)^(E$5-1) | F10: =(1+ESC_FEE)^(F$5-1) | G10: =(1+ESC_FEE)^(G$5-1) | H10: =(1+ESC_FEE)^(H$5-1) | I10: =(1+ESC_FEE)^(I$5-1) | J10: =(1+ESC_FEE)^(J$5-1) | K10: =(1+ESC_FEE)^(K$5-1) | ... W10: =(1+ESC_FEE)^(W$5-1)
A11: CfD strike escalation factor | B11: index | D11: =(1+ESC_STRIKE)^(D$5-1) | E11: =(1+ESC_STRIKE)^(E$5-1) | F11: =(1+ESC_STRIKE)^(F$5-1) | G11: =(1+ESC_STRIKE)^(G$5-1) | H11: =(1+ESC_STRIKE)^(H$5-1) | I11: =(1+ESC_STRIKE)^(I$5-1) | J11: =(1+ESC_STRIKE)^(J$5-1) | K11: =(1+ESC_STRIKE)^(K$5-1) | ... W11: =(1+ESC_STRIKE)^(W$5-1)
A13: REVENUE (USD)
A14: Generator FMP market revenue | B14: USD | D14: =DPPA_FMP_REV_Y1*D10*D9 | E14: =DPPA_FMP_REV_Y1*E10*E9 | F14: =DPPA_FMP_REV_Y1*F10*F9 | G14: =DPPA_FMP_REV_Y1*G10*G9 | H14: =DPPA_FMP_REV_Y1*H10*H9 | I14: =DPPA_FMP_REV_Y1*I10*I9 | J14: =DPPA_FMP_REV_Y1*J10*J9 | K14: =DPPA_FMP_REV_Y1*K10*K9 | ... W14: =DPPA_FMP_REV_Y1*W10*W9
A15: CfD strike leg (P_c × Q_cfd) | B15: USD | D15: =DPPA_CFD_STRIKE_Y1*D11 | E15: =DPPA_CFD_STRIKE_Y1*E11 | F15: =DPPA_CFD_STRIKE_Y1*F11 | G15: =DPPA_CFD_STRIKE_Y1*G11 | H15: =DPPA_CFD_STRIKE_Y1*H11 | I15: =DPPA_CFD_STRIKE_Y1*I11 | J15: =DPPA_CFD_STRIKE_Y1*J11 | K15: =DPPA_CFD_STRIKE_Y1*K11 | ... W15: =DPPA_CFD_STRIKE_Y1*W11
A16: CfD market offset (FMP × Q_cfd) | B16: USD | D16: =DPPA_CFD_OFFSET_Y1*D10 | E16: =DPPA_CFD_OFFSET_Y1*E10 | F16: =DPPA_CFD_OFFSET_Y1*F10 | G16: =DPPA_CFD_OFFSET_Y1*G10 | H16: =DPPA_CFD_OFFSET_Y1*H10 | I16: =DPPA_CFD_OFFSET_Y1*I10 | J16: =DPPA_CFD_OFFSET_Y1*J10 | K16: =DPPA_CFD_OFFSET_Y1*K10 | ... W16: =DPPA_CFD_OFFSET_Y1*W10
A17: CfD net settlement (to generator) | B17: USD | D17: =D15-D16 | E17: =E15-E16 | F17: =F15-F16 | G17: =G15-G16 | H17: =H15-H16 | I17: =I15-I16 | J17: =J15-J16 | K17: =K15-K16 | ... W17: =W15-W16
A18: Generator revenue (FMP + CfD net) | B18: USD | D18: =D14+D17 | E18: =E14+E17 | F18: =F14+F17 | G18: =G14+G17 | H18: =H14+H17 | I18: =I14+I17 | J18: =J14+J17 | K18: =K14+K17 | ... W18: =W14+W17
A19: Demand charge savings (total) | B19: USD | D19: =BASE_DEMAND_SAVINGS*D7 | E19: =BASE_DEMAND_SAVINGS*E7 | F19: =BASE_DEMAND_SAVINGS*F7 | G19: =BASE_DEMAND_SAVINGS*G7 | H19: =BASE_DEMAND_SAVINGS*H7 | I19: =BASE_DEMAND_SAVINGS*I7 | J19: =BASE_DEMAND_SAVINGS*J7 | K19: =BASE_DEMAND_SAVINGS*K7 | ... W19: =BASE_DEMAND_SAVINGS*W7
A20: ESCO share of demand savings | B20: USD | D20: =D19*DEMAND_SHARE | E20: =E19*DEMAND_SHARE | F20: =F19*DEMAND_SHARE | G20: =G19*DEMAND_SHARE | H20: =H19*DEMAND_SHARE | I20: =I19*DEMAND_SHARE | J20: =J19*DEMAND_SHARE | K20: =K19*DEMAND_SHARE | ... W20: =W19*DEMAND_SHARE
A21: Total developer revenue | B21: USD | D21: =D18+D20 | E21: =E18+E20 | F21: =F18+F20 | G21: =G18+G20 | H21: =H18+H20 | I21: =I18+I20 | J21: =J18+J20 | K21: =K18+K20 | ... W21: =W18+W20
A23: OPERATING COSTS (USD)
A24: O&M | B24: USD | D24: =OM_YEAR1*D8 | E24: =OM_YEAR1*E8 | F24: =OM_YEAR1*F8 | G24: =OM_YEAR1*G8 | H24: =OM_YEAR1*H8 | I24: =OM_YEAR1*I8 | J24: =OM_YEAR1*J8 | K24: =OM_YEAR1*K8 | ... W24: =OM_YEAR1*W8
A25: Equipment replacement (engine schedule) | B25: USD | D25: 0 | E25: 0 | F25: 0 | G25: 0 | H25: 0 | I25: 0 | J25: 0 | K25: 0 | L25: 0 | M25: 198572.8 | N25: 135799.63 | O25: 0 | P25: 0 | Q25: 0 | R25: 0 | S25: 0 | T25: 0 | U25: 0 | V25: 0 | W25: 0
A26: EBITDA | B26: USD | D26: =D21-D24-D25 | E26: =E21-E24-E25 | F26: =F21-F24-F25 | G26: =G21-G24-G25 | H26: =H21-H24-H25 | I26: =I21-I24-I25 | J26: =J21-J24-J25 | K26: =K21-K24-K25 | ... W26: =W21-W24-W25
A28: DEBT SCHEDULE (USD)
A29: Opening debt balance | B29: USD | D29: =DEBT_PRINCIPAL | E29: =D33 | F29: =E33 | G29: =F33 | H29: =G33 | I29: =H33 | J29: =I33 | K29: =J33 | L29: =K33 | ... W29: =V33
A30: Interest | B30: USD | D30: =IF(D$5<=DEBT_TERM_YEARS,D29*DEBT_RATE,0) | E30: =IF(E$5<=DEBT_TERM_YEARS,E29*DEBT_RATE,0) | F30: =IF(F$5<=DEBT_TERM_YEARS,F29*DEBT_RATE,0) | G30: =IF(G$5<=DEBT_TERM_YEARS,G29*DEBT_RATE,0) | H30: =IF(H$5<=DEBT_TERM_YEARS,H29*DEBT_RATE,0) | I30: =IF(I$5<=DEBT_TERM_YEARS,I29*DEBT_RATE,0) | J30: =IF(J$5<=DEBT_TERM_YEARS,J29*DEBT_RATE,0) | K30: =IF(K$5<=DEBT_TERM_YEARS,K29*DEBT_RATE,0) | ... W30: =IF(W$5<=DEBT_TERM_YEARS,W29*DEBT_RATE,0)
A31: Principal repayment | B31: USD | D31: =IF(D$5<=DEBT_TERM_YEARS,MIN(MAX(DEBT_PAYMENT-D30,0),D29),0) | E31: =IF(E$5<=DEBT_TERM_YEARS,MIN(MAX(DEBT_PAYMENT-E30,0),E29),0) | F31: =IF(F$5<=DEBT_TERM_YEARS,MIN(MAX(DEBT_PAYMENT-F30,0),F29),0) | G31: =IF(G$5<=DEBT_TERM_YEARS,MIN(MAX(DEBT_PAYMENT-G30,0),G29),0) | H31: =IF(H$5<=DEBT_TERM_YEARS,MIN(MAX(DEBT_PAYMENT-H30,0),H29),0) | I31: =IF(I$5<=DEBT_TERM_YEARS,MIN(MAX(DEBT_PAYMENT-I30,0),I29),0) | J31: =IF(J$5<=DEBT_TERM_YEARS,MIN(MAX(DEBT_PAYMENT-J30,0),J29),0) | K31: =IF(K$5<=DEBT_TERM_YEARS,MIN(MAX(DEBT_PAYMENT-K30,0),K29),0) | ... W31: =IF(W$5<=DEBT_TERM_YEARS,MIN(MAX(DEBT_PAYMENT-W30,0),W29),0)
A32: Debt service | B32: USD | D32: =D30+D31 | E32: =E30+E31 | F32: =F30+F31 | G32: =G30+G31 | H32: =H30+H31 | I32: =I30+I31 | J32: =J30+J31 | K32: =K30+K31 | ... W32: =W30+W31
A33: Closing debt balance | B33: USD | D33: =D29-D31 | E33: =E29-E31 | F33: =F29-F31 | G33: =G29-G31 | H33: =H29-H31 | I33: =I29-I31 | J33: =J29-J31 | K33: =K29-K31 | ... W33: =W29-W31
A35: DEPRECIATION & VIETNAM CIT (USD)
A36: PV depreciation (straight-line) | B36: USD | D36: =IF(D$5<=PV_DEP_YEARS,PV_CAPEX/PV_DEP_YEARS,0) | E36: =IF(E$5<=PV_DEP_YEARS,PV_CAPEX/PV_DEP_YEARS,0) | F36: =IF(F$5<=PV_DEP_YEARS,PV_CAPEX/PV_DEP_YEARS,0) | G36: =IF(G$5<=PV_DEP_YEARS,PV_CAPEX/PV_DEP_YEARS,0) | H36: =IF(H$5<=PV_DEP_YEARS,PV_CAPEX/PV_DEP_YEARS,0) | I36: =IF(I$5<=PV_DEP_YEARS,PV_CAPEX/PV_DEP_YEARS,0) | J36: =IF(J$5<=PV_DEP_YEARS,PV_CAPEX/PV_DEP_YEARS,0) | K36: =IF(K$5<=PV_DEP_YEARS,PV_CAPEX/PV_DEP_YEARS,0) | ... W36: =IF(W$5<=PV_DEP_YEARS,PV_CAPEX/PV_DEP_YEARS,0)
A37: BESS depreciation (straight-line) | B37: USD | D37: =IF(D$5<=BESS_DEP_YEARS,BESS_CAPEX/BESS_DEP_YEARS,0) | E37: =IF(E$5<=BESS_DEP_YEARS,BESS_CAPEX/BESS_DEP_YEARS,0) | F37: =IF(F$5<=BESS_DEP_YEARS,BESS_CAPEX/BESS_DEP_YEARS,0) | G37: =IF(G$5<=BESS_DEP_YEARS,BESS_CAPEX/BESS_DEP_YEARS,0) | H37: =IF(H$5<=BESS_DEP_YEARS,BESS_CAPEX/BESS_DEP_YEARS,0) | I37: =IF(I$5<=BESS_DEP_YEARS,BESS_CAPEX/BESS_DEP_YEARS,0) | J37: =IF(J$5<=BESS_DEP_YEARS,BESS_CAPEX/BESS_DEP_YEARS,0) | K37: =IF(K$5<=BESS_DEP_YEARS,BESS_CAPEX/BESS_DEP_YEARS,0) | ... W37: =IF(W$5<=BESS_DEP_YEARS,BESS_CAPEX/BESS_DEP_YEARS,0)
A38: Replacement depreciation (in-service yr 10) | B38: USD | D38: =IF(AND(D$5>=10,D$5<=10+BESS_DEP_YEARS-1),$M$25/BESS_DEP_YEARS,0) | E38: =IF(AND(E$5>=10,E$5<=10+BESS_DEP_YEARS-1),$M$25/BESS_DEP_YEARS,0) | F38: =IF(AND(F$5>=10,F$5<=10+BESS_DEP_YEARS-1),$M$25/BESS_DEP_YEARS,0) | G38: =IF(AND(G$5>=10,G$5<=10+BESS_DEP_YEARS-1),$M$25/BESS_DEP_YEARS,0) | H38: =IF(AND(H$5>=10,H$5<=10+BESS_DEP_YEARS-1),$M$25/BESS_DEP_YEARS,0) | I38: =IF(AND(I$5>=10,I$5<=10+BESS_DEP_YEARS-1),$M$25/BESS_DEP_YEARS,0) | J38: =IF(AND(J$5>=10,J$5<=10+BESS_DEP_YEARS-1),$M$25/BESS_DEP_YEARS,0) | K38: =IF(AND(K$5>=10,K$5<=10+BESS_DEP_YEARS-1),$M$25/BESS_DEP_YEARS,0) | ... W38: =IF(AND(W$5>=10,W$5<=10+BESS_DEP_YEARS-1),$M$25/BESS_DEP_YEARS,0)
A39: Replacement depreciation (in-service yr 11) | B39: USD | D39: =IF(AND(D$5>=11,D$5<=11+BESS_DEP_YEARS-1),$N$25/BESS_DEP_YEARS,0) | E39: =IF(AND(E$5>=11,E$5<=11+BESS_DEP_YEARS-1),$N$25/BESS_DEP_YEARS,0) | F39: =IF(AND(F$5>=11,F$5<=11+BESS_DEP_YEARS-1),$N$25/BESS_DEP_YEARS,0) | G39: =IF(AND(G$5>=11,G$5<=11+BESS_DEP_YEARS-1),$N$25/BESS_DEP_YEARS,0) | H39: =IF(AND(H$5>=11,H$5<=11+BESS_DEP_YEARS-1),$N$25/BESS_DEP_YEARS,0) | I39: =IF(AND(I$5>=11,I$5<=11+BESS_DEP_YEARS-1),$N$25/BESS_DEP_YEARS,0) | J39: =IF(AND(J$5>=11,J$5<=11+BESS_DEP_YEARS-1),$N$25/BESS_DEP_YEARS,0) | K39: =IF(AND(K$5>=11,K$5<=11+BESS_DEP_YEARS-1),$N$25/BESS_DEP_YEARS,0) | ... W39: =IF(AND(W$5>=11,W$5<=11+BESS_DEP_YEARS-1),$N$25/BESS_DEP_YEARS,0)
A40: Total depreciation | B40: USD | D40: =D36+D37+D38+D39 | E40: =E36+E37+E38+E39 | F40: =F36+F37+F38+F39 | G40: =G36+G37+G38+G39 | H40: =H36+H37+H38+H39 | I40: =I36+I37+I38+I39 | J40: =J36+J37+J38+J39 | K40: =K36+K37+K38+K39 | ... W40: =W36+W37+W38+W39
A41: Taxable income before loss relief (EBT) | B41: USD | D41: =D26+D25-D40-D30 | E41: =E26+E25-E40-E30 | F41: =F26+F25-F40-F30 | G41: =G26+G25-G40-G30 | H41: =H26+H25-H40-H30 | I41: =I26+I25-I40-I30 | J41: =J26+J25-J40-J30 | K41: =K26+K25-K40-K30 | ... W41: =W26+W25-W40-W30
A42: New tax loss arising | B42: USD | D42: =MAX(-D41,0) | E42: =MAX(-E41,0) | F42: =MAX(-F41,0) | G42: =MAX(-G41,0) | H42: =MAX(-H41,0) | I42: =MAX(-I41,0) | J42: =MAX(-J41,0) | K42: =MAX(-K41,0) | ... W42: =MAX(-W41,0)
A43: Assessable income (pre-relief) | B43: USD | D43: =MAX(D41,0) | E43: =MAX(E41,0) | F43: =MAX(F41,0) | G43: =MAX(G41,0) | H43: =MAX(H41,0) | I43: =MAX(I41,0) | J43: =MAX(J41,0) | K43: =MAX(K41,0) | ... W43: =MAX(W41,0)
A44: Loss vintage aged 1y - available | B44: USD | D44: 0 | E44: =D42 | F44: =E42 | G44: =F42 | H44: =G42 | I44: =H42 | J44: =I42 | K44: =J42 | L44: =K42 | ... W44: =V42
A45: Loss vintage aged 2y - available | B45: USD | D45: 0 | E45: =MAX(D44-D53,0) | F45: =MAX(E44-E53,0) | G45: =MAX(F44-F53,0) | H45: =MAX(G44-G53,0) | I45: =MAX(H44-H53,0) | J45: =MAX(I44-I53,0) | K45: =MAX(J44-J53,0) | L45: =MAX(K44-K53,0) | ... W45: =MAX(V44-V53,0)
...

Sheet FX Sensitivity
A1: FX Sensitivity - VND depreciation vs USD returns
A2: Cash flows are VND-denominated (EVN tariff / DPPA settlement) but reported in USD at the fixed contract rate. Each scenario deflates the year-t USD equity cash flow by (1+d)^t. Debt is assumed VND-denominated, so DSCR is unchanged. The rate cells are editable; engine columns validate the default scenarios.
A4: VND depreciation (per year) | B4: Equity IRR (USD) | C4: Equity NPV (USD) | D4: Equity IRR (engine) | E4: Equity NPV (engine) | F4: Status
A5: 0 | B5: =IRR(B12:V12) | C5: =NPV(DISC_RATE,C12:V12)+B12 | D5: 0.28385393 | E5: 1137682.3 | F5: =IF(AND(ABS(B5-D5)<=0.0005,ABS(C5-E5)<=1.0),"PASS","REVIEW")
A6: 0.01 | B6: =IRR(B13:V13) | C6: =NPV(DISC_RATE,C13:V13)+B13 | D6: 0.2711425 | E6: 982259.67 | F6: =IF(AND(ABS(B6-D6)<=0.0005,ABS(C6-E6)<=1.0),"PASS","REVIEW")
A7: 0.02 | B7: =IRR(B14:V14) | C7: =NPV(DISC_RATE,C14:V14)+B14 | D7: 0.25868032 | E7: 847452.46 | F7: =IF(AND(ABS(B7-D7)<=0.0005,ABS(C7-E7)<=1.0),"PASS","REVIEW")
A8: 0.03 | B8: =IRR(B15:V15) | C8: =NPV(DISC_RATE,C15:V15)+B15 | D8: 0.24646013 | E8: 730105.58 | F8: =IF(AND(ABS(B8-D8)<=0.0005,ABS(C8-E8)<=1.0),"PASS","REVIEW")
A10: Helper - FX-adjusted equity cash flow per scenario (USD): CF_t / (1 + d)^t
B11: 0 | C11: 1 | D11: 2 | E11: 3 | F11: 4 | G11: 5 | H11: 6 | I11: 7 | J11: 8 | K11: 9 | L11: 10 | M11: 11 | N11: 12 | O11: 13 | P11: 14 | Q11: 15 | R11: 16 | S11: 17 | T11: 18 | U11: 19 | V11: 20
A12: =A5 | B12: ='Pro Forma (Audit)'!C65/(1+$A5)^B$11 | C12: ='Pro Forma (Audit)'!D65/(1+$A5)^C$11 | D12: ='Pro Forma (Audit)'!E65/(1+$A5)^D$11 | E12: ='Pro Forma (Audit)'!F65/(1+$A5)^E$11 | F12: ='Pro Forma (Audit)'!G65/(1+$A5)^F$11 | G12: ='Pro Forma (Audit)'!H65/(1+$A5)^G$11 | H12: ='Pro Forma (Audit)'!I65/(1+$A5)^H$11 | I12: ='Pro Forma (Audit)'!J65/(1+$A5)^I$11 | ... V12: ='Pro Forma (Audit)'!W65/(1+$A5)^V$11
A13: =A6 | B13: ='Pro Forma (Audit)'!C65/(1+$A6)^B$11 | C13: ='Pro Forma (Audit)'!D65/(1+$A6)^C$11 | D13: ='Pro Forma (Audit)'!E65/(1+$A6)^D$11 | E13: ='Pro Forma (Audit)'!F65/(1+$A6)^E$11 | F13: ='Pro Forma (Audit)'!G65/(1+$A6)^F$11 | G13: ='Pro Forma (Audit)'!H65/(1+$A6)^G$11 | H13: ='Pro Forma (Audit)'!I65/(1+$A6)^H$11 | I13: ='Pro Forma (Audit)'!J65/(1+$A6)^I$11 | ... V13: ='Pro Forma (Audit)'!W65/(1+$A6)^V$11
A14: =A7 | B14: ='Pro Forma (Audit)'!C65/(1+$A7)^B$11 | C14: ='Pro Forma (Audit)'!D65/(1+$A7)^C$11 | D14: ='Pro Forma (Audit)'!E65/(1+$A7)^D$11 | E14: ='Pro Forma (Audit)'!F65/(1+$A7)^E$11 | F14: ='Pro Forma (Audit)'!G65/(1+$A7)^F$11 | G14: ='Pro Forma (Audit)'!H65/(1+$A7)^G$11 | H14: ='Pro Forma (Audit)'!I65/(1+$A7)^H$11 | I14: ='Pro Forma (Audit)'!J65/(1+$A7)^I$11 | ... V14: ='Pro Forma (Audit)'!W65/(1+$A7)^V$11
A15: =A8 | B15: ='Pro Forma (Audit)'!C65/(1+$A8)^B$11 | C15: ='Pro Forma (Audit)'!D65/(1+$A8)^C$11 | D15: ='Pro Forma (Audit)'!E65/(1+$A8)^D$11 | E15: ='Pro Forma (Audit)'!F65/(1+$A8)^E$11 | F15: ='Pro Forma (Audit)'!G65/(1+$A8)^F$11 | G15: ='Pro Forma (Audit)'!H65/(1+$A8)^G$11 | H15: ='Pro Forma (Audit)'!I65/(1+$A8)^H$11 | I15: ='Pro Forma (Audit)'!J65/(1+$A8)^I$11 | ... V15: ='Pro Forma (Audit)'!W65/(1+$A8)^V$11

Sheet Buyer Analysis
B1: Buyer Analysis - Cost vs Business-As-Usual
B2: Annual electricity cost with the project compared against the EVN-only baseline (USD)
B4: Year 1 Snapshot
B5: Year 1 BAU Cost (USD) | C5: 731030.93
B6: Year 1 Cost With Project (USD) | C6: 805683.4
B7: Year 1 Savings (USD) | C7: -74652.466
B8: Year 1 Savings (% of BAU) | C8: -0.10211944
B9: of which C_DN spot energy (USD) | C9: 174753.55
B10: of which C_DPPA + C_CL fees (USD) | C10: 65483.291
B11: of which C_BL retail shortfall (USD) | C11: 481870.22
B12: of which CfD payment, net (USD) | C12: 83576.336 | D12: Positive = buyer pays generator
B13: First 10 Years Savings (USD) | C13: -898833.73 | D13: Cumulative, years 1-10
B14: First 10 Years Savings (% of BAU) | C14: -0.10240977
B15: Lifetime Savings (USD) | C15: -2236896.5 | D15: Cumulative over analysis period
B16: Lifetime Savings (% of BAU) | C16: -0.10275748
A18: Year | B18: BAU Cost (USD) | C18: Cost With Project (USD) | D18: Savings (USD) | E18: Savings (% of BAU) | F18: Cumulative Savings (USD)
A19: 1 | B19: 731030.93 | C19: 805683.4 | D19: -74652.466 | E19: -0.10211944 | F19: -74652.466
A20: 2 | B20: 760272.17 | C20: 837957.14 | D20: -77684.969 | E20: -0.10218047 | F20: -152337.44
A21: 3 | B21: 790683.05 | C21: 871523.44 | D21: -80840.387 | E21: -0.1022412 | F21: -233177.82
A22: 4 | B22: 822310.38 | C22: 906434.07 | D22: -84123.692 | E22: -0.10230163 | F22: -317301.51
A23: 5 | B23: 855202.79 | C23: 942742.85 | D23: -87540.059 | E23: -0.10236176 | F23: -404841.57
A24: 6 | B24: 889410.9 | C24: 980505.77 | D24: -91094.87 | E24: -0.10242158 | F24: -495936.44
A25: 7 | B25: 924987.34 | C25: 1019781.1 | D25: -94793.725 | E25: -0.10248111 | F25: -590730.17
A26: 8 | B26: 961986.83 | C26: 1060629.3 | D26: -98642.451 | E26: -0.10254033 | F26: -689372.62
A27: 9 | B27: 1000466.3 | C27: 1103113.4 | D27: -102647.11 | E27: -0.10259927 | F27: -792019.73
A28: 10 | B28: 1040485 | C28: 1147299 | D28: -106814 | E28: -0.1026579 | F28: -898833.73
A29: 11 | B29: 1082104.4 | C29: 1193254.1 | D29: -111149.7 | E29: -0.10271625 | F29: -1009983.4
A30: 12 | B30: 1125388.5 | C30: 1241049.5 | D30: -115661.02 | E30: -0.1027743 | F30: -1125644.4
... A38: 20 | B38: 1540171.9 | C38: 1699161.4 | D38: -158989.46 | E38: -0.10322839 | F38: -2236896.5

Sheet Developer Returns
B1: Developer Returns - Financing & Cash Flow
B2: Seller/ESCO investment case: sources & uses, return metrics and annual equity cash flow (USD)
B4: Sources & Uses
B5: Total Investment (USD) | C5: 1556569.1
B6: Debt Principal (USD) | C6: 1089598.4
B7: Equity Investment (USD) | C7: 466970.74
B9: Return Metrics
B10: Equity IRR | C10: 0.28385393
B11: Project IRR | C11: 0.18337348
B12: NPV (USD) | C12: 1137682.3 | D12: At owner discount rate
B13: Minimum DSCR (debt years) | C13: 0.91308881
B14: Average DSCR | C14: 1.7116866
B15: Simple Payback (Years) | C15: 4.1772135
B16: ROI (cumulative equity CF / equity) | C16: 10.700503
A18: Year | B18: Revenue (USD) | C18: O&M + Replacement (USD) | D18: CIT (USD) | E18: CFADS (USD) | F18: Debt Service (USD) | G18: DSCR | H18: Equity Cash Flow (USD) | I18: Cumulative Equity CF (USD)
A19: 1 | B19: 281186.54 | C19: 18960.679 | D19: 0 | E19: 262225.86 | F19: 166063.19 | G19: 1.5790728 | H19: 96162.673 | I19: -370808.06
A20: 2 | B20: 291406.43 | C20: 19529.499 | D20: 0 | E20: 271876.93 | F20: 166063.19 | G20: 1.6371896 | H20: 105813.74 | I20: -264994.32
A21: 3 | B21: 301999.35 | C21: 20115.384 | D21: 0 | E21: 281883.97 | F21: 166063.19 | G21: 1.6974501 | H21: 115820.78 | I21: -149173.54
A22: 4 | B22: 312978.99 | C22: 20718.846 | D22: 0 | E22: 292260.15 | F22: 166063.19 | G22: 1.7599334 | H22: 126196.96 | I22: -22976.584
A23: 5 | B23: 324359.52 | C23: 21340.411 | D23: 7301.1062 | E23: 295718.01 | F23: 166063.19 | G23: 1.7807559 | H23: 129654.82 | I23: 106678.23
A24: 6 | B24: 336155.65 | C24: 21980.624 | D24: 8291.4993 | E24: 305883.53 | F24: 166063.19 | G24: 1.8419707 | H24: 139820.34 | I24: 246498.57
A25: 7 | B25: 348382.62 | C25: 22640.042 | D25: 9339.2451 | E25: 316403.33 | F25: 166063.19 | G25: 1.9053189 | H25: 150340.15 | I25: 396838.72
A26: 8 | B26: 361056.24 | C26: 23319.244 | D26: 10448.23 | E26: 327288.77 | F26: 166063.19 | G26: 1.9708689 | H26: 161225.58 | I26: 558064.29
A27: 9 | B27: 374192.9 | C27: 24018.821 | D27: 12863.716 | E27: 337310.36 | F27: 166063.19 | G27: 2.0312169 | H27: 171247.17 | I27: 729311.47
A28: 10 | B28: 387809.59 | C28: 223312.19 | D28: 12866.961 | E28: 151630.44 | F28: 166063.19 | G28: 0.91308881 | H28: -14432.749 | I28: 714878.72
A29: 11 | B29: 401923.93 | C29: 161281.2 | D29: 13337.3 | E29: 227305.43 | F29: 0 | H29: 227305.43 | I29: 942184.15
A30: 12 | B30: 416554.19 | C30: 26246.014 | D30: 14030.59 | E30: 376277.59 | F30: 0 | H30: 376277.59 | I30: 1318461.7
A31: 13 | B31: 431719.32 | C31: 27033.395 | D31: 14749.478 | E31: 389936.45 | F31: 0 | H31: 389936.45 | I31: 1708398.2
A32: 14 | B32: 447438.95 | C32: 27844.396 | D32: 30989.819 | E32: 388604.74 | F32: 0 | H32: 388604.74 | I32: 2097002.9
A33: 15 | B33: 463733.47 | C33: 28679.728 | D33: 32535.737 | E33: 402518 | F33: 0 | H33: 402518 | I33: 2499520.9
A34: 16 | B34: 480623.97 | C34: 29540.12 | D34: 68277.496 | E34: 382806.35 | F34: 0 | H34: 382806.35 | I34: 2882327.3
A35: 17 | B35: 498132.37 | C35: 30426.324 | D35: 71601.935 | E35: 396104.11 | F35: 0 | H35: 396104.11 | I35: 3278431.4
A36: 18 | B36: 516281.37 | C36: 31339.114 | D36: 80013.497 | E36: 404928.76 | F36: 0 | H36: 404928.76 | I36: 3683360.1
A37: 19 | B37: 535094.51 | C37: 32279.287 | D37: 86983.082 | E37: 415832.14 | F37: 0 | H37: 415832.14 | I37: 4099192.3
A38: 20 | B38: 554596.21 | C38: 33247.666 | D38: 90689.747 | E38: 430658.8 | F38: 0 | H38: 430658.8 | I38: 4529851.1

Sheet Technical Results
A1: Metric | B1: Value
A2: System Sizing
A3: PV Size (kW) | B3: 2829.159
A4: Battery Power (kW) | B4: 306.08
A5: Battery Energy (kWh) | B5: 1450.72
A7: Annual Energy Balance (Year 1)
A8: PV to Load (kWh) | B8: 3005305.9
A9: PV to Storage (kWh) | B9: 434798.62
A10: PV to Grid (kWh) | B10: 0
A11: Storage to Load (kWh) | B11: 391121.39
A12: Grid to Load (kWh) | B12: 6070538.5
A13: PV Curtailed (kWh) | B13: 543471.89
A14: Grid to Storage (kWh) | B14: 0
A16: Year-1 Utility Bill Comparison
A17: BAU Utility Bill (USD) | B17: 731030.93
A18: Optimized Utility Bill (USD) | B18: 473979.31
A19: Utility Bill Savings (USD) | B19: 257051.62
A20: BAU Demand Charge (USD) | B20: 0
A21: Optimized Demand Charge (USD) | B21: 0
A22: Demand Charge Savings (USD) | B22: 0
A24: Solar Resource (Year 1)
A25: Annual POA Irradiation (kWh/m²) | B25: 1929.6822
A26: Performance Ratio (Year 1) | B26: 0.72967589

Sheet Dispatch Profile
A1: Hour | B1: Load (kW) | C1: PV Irradiation (W/m²) | D1: PV Generation Total (kW) | E1: PV to Load (kW) | F1: PV to Storage (kW) | G1: PV to Grid (kW) | H1: PV Curtailed (kW) | I1: Grid to Load (kW) | J1: Grid to Storage (kW) | K1: Storage to Load (kW)
A2: 1 | B2: 1020 | C2: 0 | D2: 0 | E2: 0 | F2: 0 | G2: 0 | H2: 0 | I2: 1020 | J2: 0 | K2: 0
A3: 2 | B3: 1078.4 | C3: 0 | D3: 0 | E3: 0 | F3: 0 | G3: 0 | H3: 0 | I3: 1078.4 | J3: 0 | K3: 0
A4: 3 | B4: 906.4 | C4: 0 | D4: 0 | E4: 0 | F4: 0 | G4: 0 | H4: 0 | I4: 906.4 | J4: 0 | K4: 0
A5: 4 | B5: 860.8 | C5: 0 | D5: 0 | E5: 0 | F5: 0 | G5: 0 | H5: 0 | I5: 860.8 | J5: 0 | K5: 0
A6: 5 | B6: 996.8 | C6: 0 | D6: 0 | E6: 0 | F6: 0 | G6: 0 | H6: 0 | I6: 996.8 | J6: 0 | K6: 0
A7: 6 | B7: 983.2 | C7: 0 | D7: 0 | E7: 0 | F7: 0 | G7: 0 | H7: 0 | I7: 876.732 | J7: 0 | K7: 110.59946
A8: 7 | B8: 586.4 | C8: 11.75 | D8: 8.2979723 | E8: 8.2979723 | F8: 0 | G8: 0 | H8: 0 | I8: 272.329 | J8: 0 | K8: 317.96047
A9: 8 | B9: 104.269 | C9: 120.27 | D9: 256.75721 | E9: 108.31513 | F9: -148.44208 | G9: 0 | H9: 0 | I9: 0 | J9: 0 | K9: 0
A10: 9 | B10: 89.172 | C10: 270.88 | D10: 600.8374 | E10: 92.632297 | F10: -317.96047 | G10: 0 | H10: 190.24462 | I10: 0 | J10: 0 | K10: 0
A11: 10 | B11: 105.232 | C11: 505.48 | D11: 1114.7113 | E11: 109.3155 | F11: -317.96047 | G11: 0 | H11: 687.43528 | I11: 0 | J11: 0 | K11: 0
A12: 11 | B12: 89.626 | C12: 573.07 | D12: 1243.8939 | E12: 93.103914 | F12: -317.96047 | G12: 0 | H12: 832.8295 | I12: 0 | J12: 0 | K12: 0
A13: 12 | B13: 119.641 | C13: 477.66 | D13: 1027.0756 | E13: 124.28468 | F13: -169.51735 | G13: 0 | H13: 733.27357 | I13: 0 | J13: 0 | K13: 0
... A8761: 8760 | B8761: 1216 | C8761: 0 | D8761: 0 | E8761: 0 | F8761: 0 | G8761: 0 | H8761: 0 | I8761: 1216 | J8761: 0 | K8761: 0

Sheet Load Duration
A1: Rank | B1: Load (kW) | C1: Net Load (kW)
A2: 1 | B2: 2428 | C2: 2428
A3: 2 | B3: 2418.5558 | C3: 2418.556
A4: 3 | B4: 2414.4 | C4: 2414.4
A5: 4 | B5: 2405.0087 | C5: 2405.009
A6: 5 | B6: 2390.381 | C6: 2379.2
A7: 6 | B7: 2389.6 | C7: 2369.946
A8: 7 | B8: 2387.844 | C8: 2361.036
A9: 8 | B9: 2381.0831 | C9: 2330.4
A10: 9 | B10: 2380.3051 | C10: 2321.335
A11: 10 | B11: 2379.2 | C11: 2238.145
A12: 11 | B12: 2378.556 | C12: 2208.8
A13: 12 | B13: 2369.9456 | C13: 2200.208
... A8761: 8760 | B8761: 0 | C8761: 0

Sheet Year 1 BAU vs DPPA
A1: Line Item | B1: Year 1 (USD) | C1: Side
A2: Buyer (Factory) - Year 1 Outflow (USD)
A3: BAU EVN energy + demand bill | B3: 731030.93 | C3: bau
A4: C_DN spot energy (Q_Khc × CFMP × K_pp) | B4: 174753.55 | C4: dppa
A5: C_DPPA system service fee | B5: 45048.7 | C5: dppa
A6: C_CL settlement adder | B6: 20434.591 | C6: dppa
A7: C_BL retail shortfall (P_evn × shortfall) | B7: 481870.22 | C7: dppa
A8: CfD payment to ESCO (positive = pay) | B8: 83576.336 | C8: dppa
A9: Optimized demand charge (kept by EVN) | B9: 0 | C9: dppa
A10: ESCO demand savings share charged back | B10: 0 | C10: dppa
A11: Total buyer outflow | B11: 805683.4 | C11: both
A12: Buyer savings vs BAU | B12: -74652.466 | C12: delta
A13: Buyer savings as % of BAU | B13: -0.10211944 | C13: delta_fraction
A14: Seller (ESCO / Generator) - Year 1 Revenue (USD)
A15: Discount-to-EVN energy revenue (Phase 2) | B15: 0 | C15: bau_esco
A16: FMP market revenue (Q_re_meter × FMP) | B16: 197610.21 | C16: dppa
A17: CfD net (from buyer) | B17: 83576.336 | C17: dppa
A18: Demand savings share (80%) | B18: 0 | C18: both_esco
A19: ESCO grid arbitrage revenue | B19: 0 | C19: both_esco
A20: Total ESCO / generator revenue | B20: 281186.54 | C20: both_esco
A21: System Energy Flows (kWh / yr)
A22: PV → load | B22: 3005305.9 | C22: flow
A23: PV → storage | B23: 434798.62 | C23: flow
A24: PV → grid (export at FMP) | B24: 543471.89 | C24: flow
A25: Storage → load | B25: 391121.39 | C25: flow
A26: Q_re_meter (total generator injection) | B26: 3939899.1 | C26: flow
A27: Q_adj (loss-adjusted customer-side) | B27: 3835336.4 | C27: flow
A28: Q_Khc (matched consumption, settled) | B28: 3291057.8 | C28: flow
A29: EVN retail shortfall | B29: 6049033.8 | C29: flow

Sheet Monthly Settlement
A1: Month | B1: C_DN (VND) | C1: C_DPPA (VND) | D1: C_CL (VND) | E1: C_BL (VND) | F1: CfD Net (VND) | G1: Generator Revenue (VND) | H1: Customer Total (VND)
A2: 1 | B2: 4.1585873e+08 | C2: 1.0029314e+08 | D2: 45494082 | E2: 1.1153492e+09 | F2: 1.6161029e+08 | G2: 6.5467987e+08 | H2: 1.8386054e+09
A3: 2 | B3: 3.9481248e+08 | C3: 99983603 | D3: 45353673 | E3: 8.8231664e+08 | F3: 1.8370192e+08 | G3: 6.6263063e+08 | H3: 1.6061683e+09
A4: 3 | B4: 5.571889e+08 | C4: 1.1772203e+08 | D4: 53400019 | E4: 1.0643384e+09 | F4: 1.264479e+08 | G4: 7.8000366e+08 | H4: 1.9190973e+09
A5: 4 | B5: 5.2231761e+08 | C5: 1.0579069e+08 | D5: 47987831 | E5: 9.6371624e+08 | F5: 91883386 | G5: 7.0105064e+08 | H5: 1.7316957e+09
A6: 5 | B6: 4.5246465e+08 | C6: 1.0853491e+08 | D6: 49232642 | E6: 9.4969746e+08 | F6: 1.7213905e+08 | G6: 6.4954105e+08 | H6: 1.7320687e+09
A7: 6 | B7: 2.3684934e+08 | C7: 94265223 | D7: 42759753 | E7: 9.9730623e+08 | F7: 2.9680835e+08 | G7: 5.4156712e+08 | H7: 1.6679889e+09
A8: 7 | B8: 2.7098089e+08 | C8: 93609029 | D8: 42462096 | E8: 9.4407446e+08 | F8: 2.6384374e+08 | G8: 5.6933761e+08 | H8: 1.6149702e+09
A9: 8 | B9: 3.4791895e+08 | C9: 91341226 | D9: 41433395 | E9: 1.1120928e+09 | F9: 1.7474373e+08 | G9: 6.1159068e+08 | H9: 1.7675301e+09
A10: 9 | B10: 2.2021947e+08 | C10: 92288055 | D10: 41862887 | E10: 1.1232787e+09 | F10: 2.9537383e+08 | G10: 5.3531953e+08 | H10: 1.7730229e+09
A11: 10 | B11: 3.2655165e+08 | C11: 83797639 | D11: 38011540 | E11: 1.24967e+09 | F11: 1.4892044e+08 | G11: 5.0819804e+08 | H11: 1.8469513e+09
A12: 11 | B12: 4.122607e+08 | C12: 99009137 | D12: 44911645 | E12: 1.1441923e+09 | F12: 1.5726568e+08 | G12: 5.8573842e+08 | H12: 1.8576395e+09
A13: 12 | B13: 4.3859491e+08 | C13: 98146136 | D13: 44520178 | E13: 1.1271544e+09 | F13: 1.2531931e+08 | G13: 5.9554877e+08 | H13: 1.833735e+09

Sheet Hourly Settlement
A1: Hour | B1: Load (kW) | C1: Q_re_meter (kW) | D1: Q_re_delivered (kW) | E1: Q_adj (kW) | F1: Q_Khc (kW) | G1: FMP (VND/kWh) | H1: C_DN (VND) | I1: C_DPPA (VND) | J1: C_CL (VND) | K1: C_BL (VND) | L1: CfD Payment (VND)
A2: 1 | B2: 1020 | C2: 0 | D2: 0 | E2: 0 | F2: 0 | G2: 1377.55 | H2: 0 | I2: 0 | J2: 0 | K2: 1213800 | L2: 0
A3: 2 | B3: 1078.4 | C3: 0 | D3: 0 | E3: 0 | F3: 0 | G3: 1316 | H3: 0 | I3: 0 | J3: 0 | K3: 1283296 | L3: 0
A4: 3 | B4: 906.4 | C4: 0 | D4: 0 | E4: 0 | F4: 0 | G4: 1367.3 | H4: 0 | I4: 0 | J4: 0 | K4: 1078616 | L4: 0
A5: 4 | B5: 860.8 | C5: 0 | D5: 0 | E5: 0 | F5: 0 | G5: 1420.5 | H5: 0 | I5: 0 | J5: 0 | K5: 1024352 | L5: 0
A6: 5 | B6: 996.8 | C6: 0 | D6: 0 | E6: 0 | F6: 0 | G6: 1423.7 | H6: 0 | I6: 0 | J6: 0 | K6: 1186192 | L6: 0
A7: 6 | B7: 983.2 | C7: 110.59946 | D7: 110.59946 | E7: 107.66421 | F7: 107.66421 | G7: 1433.15 | H7: 164130.33 | I7: 38759.117 | J7: 17581.566 | K7: 1041887.6 | L7: 61029.46
A8: 7 | B8: 586.4 | C8: 326.25845 | D8: 326.25845 | E8: 317.59973 | F8: 317.59973 | G8: 1460.05 | H8: 491831.89 | I8: 114335.9 | J8: 51864.035 | K8: 492710.9 | L8: 171487.97
A9: 8 | B9: 104.269 | C9: 108.31513 | D9: 108.31513 | E9: 105.44051 | F9: 104.269 | G9: 1481.35 | H9: 163091.23 | I9: 37536.84 | J9: 17027.128 | K9: 0 | L9: 54079.117
A10: 9 | B10: 89.172 | C10: 282.87692 | D10: 92.632297 | E10: 275.36952 | F10: 89.172 | G10: 1273.8 | H10: 119873.54 | I10: 32101.92 | J10: 14561.788 | K10: 0 | L10: 64756.706
A11: 10 | B11: 105.232 | C11: 796.75078 | D11: 109.3155 | E11: 775.60545 | F11: 105.232 | G11: 1251.7 | H11: 139185.26 | I11: 37883.52 | J11: 17184.386 | K11: 0 | L11: 78745.106
A12: 11 | B12: 89.626 | C12: 925.93342 | D12: 93.103914 | E12: 901.35965 | F12: 89.626 | G12: 1237.2 | H12: 117193.73 | I12: 32265.36 | J12: 14635.926 | K12: 0 | L12: 68366.713
A13: 12 | B13: 119.641 | C13: 857.55825 | D13: 124.28468 | E13: 834.79912 | F13: 119.641 | G13: 1241.95 | H13: 156736.63 | I13: 43070.76 | J13: 19537.375 | K13: 0 | L13: 90693.86
... A8761: 8760 | B8761: 1216 | C8761: 0 | D8761: 0 | E8761: 0 | F8761: 0 | G8761: 1658.6 | H8761: 0 | I8761: 0 | J8761: 0 | K8761: 2228928 | L8761: 0
